Workbook

Sheet ตัวชี้วัด 69
A1: รายงานผลการดำเนินงานตามตัวชี้วัดแผนพัฒนาการศึกษา ฉบับที่ 13 (พ.ศ.2566 - 2570) ฉบับปรับปรุง และแผนปฏิบัติการ ประจำปีงบประมาณ พ.ศ. 2569
A2: คณะเทคโนโลยีการประมงและทรัพยากรทางน้ำ มหาวิทยาลัยแม่โจ้
A3: ตัวชี้วัด | B3: หน่วยนับ | C3: เป้าหมาย ปีงบประมาณ 2569 | D3: ผลการดำเนินงาน | E3: ร้อยละ ความสำเร็จ | F3: รายละเอียดการดำเนินงาน / เอกสารอ้างอิง | G3: คำอธิบายเกณฑ์การประเมินตัวชี้วัด
A4: ประเด็นยุทธศาสตร์ที่ 1. การขับเคลื่อนยุทธศาสตร์มหาวิทยาลัยเชิงรุกสู่การเป็นมหาวิทยาลัยชั้นนำด้านเกษตรสุขภาวะในระดับนานาชาติ (Proactive Strategy toward Inter IWA)
A5: เป้าประสงค์ที่ 1.1 เป็นมหาวิทยาลัยชั้นนำด้านการเกษตรสุขภาวะในระดับนานาชาติ
A6: 1.1.1 ผลการจัดอันดับ World University Ranking (WUR) | B6: อันดับ | C6: อันดับที่ 1,201-1,500 ของโลก | F6: - | G6: พิจารณาจากรายงานผลการดำเนินงานที่สนับสนุนเป้าหมายของมหาวิทยาลัย เพื่อเข้าสู่การจัดอันดับ World University Ranking (WUR)-
A7: 1.1.2 ผลการจัดอันดับ SCIMAGO | B7: อันดับ | C7: 10 | F7: - | G7: พิจารณาจากรายงานผลการดำเนินงานที่สนับสนุนเป้าหมายของมหาวิทยาลัย เพื่อเข้าสู่การจัดอันดับ SCIMAGO ตามเป้าหมายที่กำหนด
A8: 1.1.3 ผลการจัดอันดับ QS ด้านเกษตรและป่าไม้ | B8: อันดับ | C8: อันดับที่ 401-450 ของโลก | F8: - | G8: พิจารณาจากรายงานผลการดำเนินงานที่สนับสนุนเป้าหมายของมหาวิทยาลัย เพื่อเข้าสู่การจัดอันดับ QS ด้านเกษตรและป่าไม้ ตามเป้าหมายที่กำหนด
A9: 1.1.4 ความสำเร็จในการร่วมสนับสนุนและขับเคลื่อนการดำเนินงานเพื่อเข้ารับการจัดอันดับ SDGs | B9: ระดับ | C9: 5 | F9: - | G9: พิจารณาจากการประเมินความสำเร็จตามกระบวนการ - มีการวิเคราะห์ข้อมูลที่เกี่ยวข้อง (1 คะแนน) - มีการวางแผนและกำหนดแนวทางการขับเคลื่อนการดำเนินงาน (1 คะแนน) - มีการจัดกิจกรรมที่เกี่ยวข้องอย่างน้อย 2 กิจกรรม โดยหนึ่งกิจกรรมต้องเกี่ยวข้องกับ SDG ที่รับผิดชอบ (1 คะแนน) - มีการรายงานผลการดำเนินงานต่อคณะกรรมการขับเคลื่อนการจัดอันดับม.สู่ความยั่งยืน (1 คะแนน) - มีการรายงานผลเข้าสู่ระบบรายงานผลกิจกรรมที่สอดคล้องกับ SDGs (1 คะแนน)
A10: 1.1.5. ความสำเร็จในการสนับสนุนมหาวิทยาลัยในการขับเคลื่อนนโยบาย Green U และ Green Office) | B10: ระดับ | C10: 3 | F10: - | G10: พิจารณาจากเกณฑ์การประเมินผลการดำเนินงานตามมติที่ประชุมคณะกรรมการขับเคลื่อนยุทธศาสตร์การเป็นมหาวิทยาลัยสีเขียว (Green University) หรือ Green Office
A11: เป้าประสงค์ที่ 1.2 เป็นมหาวิทยาลัยที่เป็นเลิศด้านเกษตรอัจฉริยะเพื่อสุขภาวะที่ดี
A12: 1.2.1 ความสำเร็จของยุทธศาสตร์เกษตรอินทรีย์ (Organic University) | B12: ร้อยละ | C12: 90 | F12: - | G12: พิจารณาจากผลการดำเนินงานการร่วมขับเคลื่อนกิจกรรมสำคัญที่จะขับเคลื่อนการดำเนินงานในปีงบประมาณ พ.ศ. 2569 ดังนี้ 1.ผลงานการเรียนการสอนด้านเกษตรอินทรีย์ 1.1 หลักสูตรด้านเกษตรอินทรีย์(Degree/non-degree) ที่เปิดสอน ในปีงบประมาณ 2569) 1.2 จำนวณบัณฑิต หรือ ผู้จบหลักสูตรด้านเกษตรอินทรีย์ 2.ผลงานวิจัยด้านเกษตรอินทรีย์ 2.1 จำนวนงบประมาณสนับสนุนงานวิจัยด้านเกษตรอินทรีย์ 3. ผลงานบริการวิชาการด้านเกษตรอินทรีย์ 3.1 จำนวนองค์ความรู้/ข้อเสนอเชิงนโยบาย ด้านเกษตรอินทรีย์ที่ได้รับการใช้ประโยชน์สู่สาธารณะ/ชุมชน 3.2 เครือข่ายเกษตรกร หรือผู้ประกอบการด้านเกษตรอินทรีย์ 4. ด้านภาพลักษณ์เกษตรอินทรีย์แม่โจ้และการบริหารจัดการ 4.1 การพัฒนาฐานข้อมูลเกษตรอินทรีย์ มหาวิทยาลัยแม่โจ้ 4.2 ความสำเร็จของ Maejo PGS 4.3 ความสำเร็จของกาด 2477 4.4 จำนวนพื้นที่อินทรีย์ภายในมหาวิทยาลัยที่ผ่านการรับรอง-
A13: 1.2.2 ความสำเร็จของการดำเนินงานด้านเกษตรอัจฉริยะ (Intelligent Agriculture) | B13: ร้อยละ | C13: 90 | F13: - | G13: พิจารณาจากผลการดำเนินงานกิจกรรมสำคัญที่จะขับเคลื่อนการดำเนินงานในปีงบประมาณ พ.ศ. 2569 ดังนี้ 1.ผลงานการเรียนการสอนด้านเกษตรอัจฉริยะ 1.1 หลักสูตรด้านเกษตรอัจฉริยะ (Degree/non-degree) ที่เปิดสอน (ในปีงบประมาณ 2569) 1.2 จำนวณบัณฑิต หรือ ผู้จบหลักสูตรด้านเกษตรอัจฉริยะ 2.ผลงานวิจัยด้านเกษตรอัจฉริยะ 2.1 จำนวนโครงการวิจัยด้านเกษตรอัจฉริยะ 3. ผลงานการบริการวิชาการด้านเกษตรอัจฉริยะ 3.1 จำนวนเทคโนโลยี นวัตกรรมและกระบวนการเกษตรสมัยใหม่และเกษตรอัจฉริยะที่ได้รับการพัฒนาต่อยอดกับชุมชน สังคม หรือพาณิชย์ 3.2 จำนวนเครือข่ายความร่วมมือและจำนวนเครือข่ายที่ได้รับการพัฒนาและขยายความร่วมมือกับกลุ่มผู้ใช้นวัตกรรมเกษตรสมัยใหม่และเกษตรอัจฉริยะ 4. ด้านภาพลักษณ์เกษตรอัจฉริยะแม่โจ้ 4.1 จำนวนพื้นที่/ศูนย์ถ่ายทอดนวัตกรรม/แหล่งเรียนรู้ และฟาร์มเกษตรสมัยใหม่และเกษตรอัจฉริยะภายในมหาวิทยาลัย
A14: 2.1.3 ความสำเร็จในการพัฒนานักศึกษาสู่การเป็นผู้มีสุขภาวะที่ดี | B14: ร้อยละ | C14: 90 | F14: - | G14: พิจารณาจากความสำเร็จของการบรรลุเป้าหมายตามตัวชี้วัดและกิจกรรมโครงการที่กำหนดดังนี้ กิจกรรมที่จะดำเนินการ 1. กิจกรรมกวดขันวินัยและสร้างจิตสำนึกวินัยจราจร (ศึกษาวิจัย) (ZT) 2. การสำรวจสุขภาพจิต (แบบสำรวจสุขภาพจิต)นักศึกษาและบุคลากร (HP) 3. กิจกรรมส่งเสริมสุขภาพให้แก่นักศึกษาและบุคลากรในกลุ่มเสี่ยงจากข้อมูลการตรวจสุขภาพประจำปีบุคลกรและข้อมูลรายงานสุขภาพนักศึกษา(HP) 4. การดำเนินงานเพื่อพัฒนานักศึกษาสู่การเป็นผู้มีสุขภาวะที่ดีของแต่ละส่วนงาน
A15: ประเด็นยุทธศาสตร์ที่ 2. การขับเคลื่อนผลการดำเนินงานตามพันธกิจหลัก (Driving Mission - Driven Performance)
A16: เป้าประสงค์ที่ 2.1 ผลิตบัณฑิตและพัฒนานักศึกษาที่ก้าวทันต่อโลกสมัยใหม่และเป็นนักปฏิบัติที่เชี่ยวชาญ
A17: 2.1.1 จำนวนนักศึกษาใหม่ระดับปริญญาตรี | B17: คน | C17: 130 | F17: - | G17: พิจารณาจากการนับจำนวนนักศึกษารับเข้าระดับปริญญาตรี (ทั้งภาคปกติและสมทบ) ลงทะเบียนเข้าศึกษาชั้นปีที่1 ในหลักสูตรทุกประเภท ประจำปีการศึกษา 2569
A18: 2.1.2 ร้อยละของผู้สำเร็จการศึกษาภายในระยะเวลาของหลักสูตร | B18: ร้อยละ | C18: 80 | F18: - | G18: พิจารณาจากจำนวนนักศึกษาชั้นปีสุดท้ายระดับปริญญาตรี (ภาคปกติ) หลักสูตร 4 ปีและ 5 ปี สำเร็จการศึกษาในปีการศึกษา 2569 / จำนวนนักศึกษาหลักสูตร 4 ปีและ 5 ปี ชั้นปีสุดท้ายทั้งหมด) x 100
A19: 2.1.3 ร้อยละของบัณฑิตที่มีงานทำหรือประกอบอาชีพอิสระภายใน 1 ปี | B19: ร้อยละ | C19: 80 | F19: - | G19: พิจารณาจากจำนวนบัณฑิตระดับปริญญาตรีที่สำเร็จในปีการศึกษา 2567 ที่ได้งานทำหรือประกอบอาชีพอิสระภายใน 1 ปี / จำนวนบัณฑิตที่ตอบแบบสำรวจทั้งหมด) X 100
A20: 2.1.4 ความพึงพอใจผู้ใช้บัณฑิต | B20: ค่าเฉลี่ย | C20: 4.4 | F20: - | G20: พิจารณาจากค่าเฉลี่ยผลการสำรวจความพึงพอใจของผู้ใช้บัณฑิต ประจำปีการศึกษา 2567 จากระบบความพึงพอใจของผู้ใช้บัณฑิต
A21: 2.1.5 รายได้เริ่มต้นเฉลี่ยต่อเดือนของบัณฑิตระดับปริญญาตรี | B21: บาท | C21: 15000 | F21: - | G21: พิจารณาจากจำนวนรายได้เฉลี่ยต่อเดือนเริ่มต้นของบัณฑิตปริญญาตรีที่สำเร็จการศึกษา ในปีการศึกษา 2567
A22: 2.1.6ค่าฐานนิยม (Mode) ผลการประเมินระดับหลักสูตร | B22: ค่าเฉลี่ย | C22: 3 | F22: - | G22: พิจารณาจากค่าฐานนิยม (Mode) จากผลการประเมินคุณภาพการศึกษาระดับหลักสูตรตามเกณฑ์ AUN-QA ของทุกหลักสูตรในปีการศึกษา 2568 **ข้อมูลอ้างอิงจากระบบรายงานผลการประเมินคุณภาพการศึกษา (QA-Report)
A23: 2.1.7 จำนวนรายวิชาเรียนรู้ตลอดชีวิต | B23: รายวิชา | C23: 2 | F23: - | G23: พิจารณาจากการนับจำนวนรายวิชาเรียนรู้ตลอดชีวิตที่คณะกรรมการวิชาการรับทราบ และมีการเปิดรับนักศึกษาในปีงบประมาณ พ.ศ. 2569
A24: 2.1.8 จำนวนรางวัลที่นักศึกษา บุคลากร ศิษย์เก่าหรือส่วนงาน ได้รับในระดับชาติ หรือนานาชาติ | B24: รางวัล | C24: 5 | F24: - | G24: พิจารณาจากการนับจำนวนรางวัลจำนวนรางวัลที่นักศึกษา บุคลากร ศิษย์เก่า หรือส่วนงาน/หน่วยงานได้รับในระดับชาติ/นานาชาติ ในปีงบประมาณ พ.ศ. 2569
A25: 2.1.9 ร้อยละของนักศึกษาชั้นปีสุดท้ายที่ผ่านกระบวนการ พัฒนาพัฒนาให้เป็นพลเมืองโลก ด้วยกระบวนการทักษะในศตวรรษที่ 21 | B25: ร้อยละ | C25: 90 | F25: - | G25: พิจารณาจากจำนวนนักศึกษาชั้นปีสุดท้ายที่ได้รับการพัฒนาตามกระบวนการพัฒนาทักษะการเรียนรู้ในศตวรรษที่ 21 / จำนวนนักศึกษาชั้นปีสุดท้ายทั้งหมด) x 100
A26: เป้าประสงค์ที่ 2.2 สร้างผลงานวิจัย เทคโนโลยีและนวัตกรรม ที่มีการบูรณาการศาสตร์ โดยใช้เกษตรเป็นรากฐาน และได้รับการยอมรับในระดับชาติและนานาชาติ
A27: 2.2.1 จำนวนเงินวิจัยด้านวิทยาศาสตร์และเทคโนโลยี | B27: บาท | C27: 5167959 | F27: - | G27: พิจารณาจากจำนวนเงินสนับสนุนโครงการวิจัยจากทุกแหล่งงบประมาณ (งบประมาณแผ่นดินและงบประมาณจากแหล่งอื่น) ที่อาจารย์/นักวิจัยประจำได้รับ ที่ได้ขึ้นทะเบียนงานวิจัยที่สำนักวิจัยฯ และบันทึกเข้าสู่ฐานข้อมูลงานวิจัยในระบบ ERP
A28: 2.2.2 ร้อยละของอาจารย์และนักวิจัยประจำที่มีผลงานวิจัย | B28: ร้อยละ | C28: 70 | G28: พิจารณาจากจำนวนอาจารย์และนักวิจัยประจำที่มีผลงานวิจัยนับเฉพาะที่เป็นหัวหน้าโครงการหรือมีความรับผิดชอบในโครงการวิจัยนั้นๆ ในปีงบประมาณ พ.ศ. 2569
A29: 2.2.3 จำนวนครั้งในการผลงานวิจัยหรืองานสร้างสรรค์ที่นำไปใช้ประโยชน์ | B29: ครั้ง | C29: 3 | G29: พิจารณาจากจำนวนครั้งในการนำผลงานวิจัยหรืองานสร้างสรรค์ของอาจารย์/นักวิจัยประจำที่มีการนำมาใช้ประโยชน์ในปีงบประมาณ พ.ศ. 2569
A30: 2.2.4 ร้อยละของผลงานวิจัยที่ได้รับการตีพิมพ์เผยแพร่ตามเกณฑ์การเผยแพร่ผลงานวิชาการของ กพอ. | B30: ร้อยละ | C30: 50 | G30: พิจารณาจากจำนวนผลงานวิจัยหรืองานสร้างสรรค์ที่ได้รับการตีพิมพ์ระดับชาติหรือนานาชาติ / จำนวนอาจารย์และนักวิจัยประจำทั้งหมด) x 100
A31: 2.2.5 ร้อยละของบทความวิจัยที่ได้รับการอ้างอิง (Citation) ต่อจำนวนอาจารย์ประจำทั้งหมด | B31: ร้อยละ | C31: 110 | G31: พิจารณาจากบทความวิจัยหรืองานสร้างสรรค์ที่ได้รับการอ้างอิง (Citation) ใน (Refereed journal หรือในฐานข้อมูลระดับนานาชาติ / จำนวนอาจารย์และนักวิจัยประจำทั้งหมด) x 100* นับอาจารย์ลาศึกษาต่อ
A32: 2.2.6 จำนวนผลงานวิจัยที่ยื่นขอจดสิทธิบัตร/อนุสิทธิบัตร/บัญชีนวัตกรรม/นวัตกรรมต้นแบบ | B32: ผลงาน | C32: 2 | G32: พิจารณาจากการนับจำนวนผลงานวิจัยที่ได้ยื่นขอจดสิทธิบัตร/อนุสิทธิบัตร/บัญชีนวัตกรรม/นวัตกรรมต้นแบบ
A33: 2.2.7 ร้อยละของผลงานวิชาการที่เสนอขอรับการจดลิขสิทธิ์ต่ออาจารย์ประจำ | B33: ร้อยละ | C33: 60 | G33: พิจารณาจากจำนวนผลงานวิชาการที่เสนอขอรับการจดลิขสิทธิ์และ/หรือได้รับรองคุณภาพจากหน่วยงานที่เชื่อถือได้ ภายในปีงบประมาณ พ.ศ. 2569 ต่อจำนวนอาจารย์ประจำทั้งหมด
A34: 2.2.8 จำนวนองค์ความรู้งานวิจัยเพื่อพัฒนาผู้เรียน | B34: เรื่อง | C34: 10 | F34: - | G34: พิจารณาจากจำนวนองค์ความรู้งานวิจัยที่นำมาสู่การพัฒนาผู้เรียน ในปีงบประมาณ พ.ศ. 2569
A35: เป้าประสงค์ที่ 2.3 ให้บริการวิชาการเพื่อเป็นที่ยอมรับจากสังคม ชุมชน และประเทศ ด้วยศาสตร์ทางด้านการเกษตร
A36: 2.3.1 จำนวนงบประมาณบริการวิชาการ | B36: บาท | C36: 745000 | F36: - | G36: พิจารณาจากการนับจำนวนงบประมาณบริการวิชาการจากทุกแหล่งทุน ในปีงบประมาณ พ.ศ. 2569
A37: 2.3.2 ผลกระทบด้านเศรษฐกิจ สังคม และคุณภาพชีวิตของชุมชนจากการบริการวิชาการ | B37: ค่าเฉลี่ย | C37: 4 | G37: พิจารณาจากค่าเฉลี่ยผลการสำรวจผลกระทบด้านเศรษฐกิจ สังคม และคุณภาพชีวิตของชุมชนเป้าหมาย ที่เกิดจากโครงการบริการวิชาการของมหาวิทยาลัยและส่วนงาน
A38: 2.3.3 ระดับความสำเร็จของการบูรณาการผลงานบริการวิชาการสู่พันธกิจอื่น | B38: ระดับ | C38: 5 | G38: พิจารณาจากจำนวนผลการนำความรู้และประสบการณ์จากการให้บริการวิชาการมาใช้ในการพัฒนาการเรียนการสอนและ/หรือการวิจัยต่อจำนวนโครงการบริการวิชาในแผนปฏิบัติการประจำปีงบประมาณ พ.ศ. 2569 โดยเทียบบัญญัติไตรยางศ์กำหนดร้อยละ 30 เท่ากับ 5 คะแนน
A39: เป้าประสงค์ที่ 2.4 เป็นแหล่งเรียนรู้ด้านศิลปวัฒนธรรมเกษตรและสิ่งแวดล้อม และสร้างสรรค์นวัตกรรมด้านทุนทางวัฒนธรรม
A40: 2.4.1 ความสำเร็จของแผนทำนุบำรุงศิลปวัฒนธรรม | B40: ร้อยละ | C40: 80 | F40: - | G40: พิจารณาจากผลการดำเนินงานตามตัวชี้วัดในแผนทำนุบำรุงศิลปวัฒนธรรม ประจำปีงบประมาณ พ.ศ. 2569
...

Sheet ตัวชี้วัด 69 (6 เดือน)
A2: รายงานผลการดำเนินงานตามตัวชี้วัดแผนพัฒนาการศึกษา ฉบับที่ 13 (พ.ศ.2566 - 2570) ฉบับปรับปรุง และแผนปฏิบัติการ ประจำปีงบประมาณ พ.ศ. 2569
A3: รอบ 6 เดือน (1 ตุลาคม 2568 - 31 มีนาคม 2569) คณะเทคโนโลยีการประมงและทรัพยากรทางน้ำ มหาวิทยาลัยแม่โจ้
A4: ตัวชี้วัด | B4: หน่วยนับ | C4: เป้าหมาย ปีงบประมาณ 2569 | D4: ผลการดำเนินงาน | E4: ร้อยละ ความสำเร็จ | F4: รายละเอียดการดำเนินงาน / เอกสารอ้างอิง | G4: คำอธิบายเกณฑ์การประเมินตัวชี้วัด
A5: ประเด็นยุทธศาสตร์ที่ 1. การขับเคลื่อนยุทธศาสตร์มหาวิทยาลัยเชิงรุกสู่การเป็นมหาวิทยาลัยชั้นนำด้านเกษตรสุขภาวะในระดับนานาชาติ (Proactive Strategy toward Inter IWA)
A6: เป้าประสงค์ที่ 1.1 เป็นมหาวิทยาลัยชั้นนำด้านการเกษตรสุขภาวะในระดับนานาชาติ
A7: 1.1.1 ผลการจัดอันดับ World University Ranking (WUR) | B7: อันดับ | C7: อันดับที่ 1,201-1,500 ของโลก | D7: 1501 | E7: 100 | F7: อ้างอิงข้อมูลจากส่วนกลาง | G7: พิจารณาจากรายงานผลการดำเนินงานที่สนับสนุนเป้าหมายของมหาวิทยาลัย เพื่อเข้าสู่การจัดอันดับ World University Ranking (WUR)-
A8: 1.1.2 ผลการจัดอันดับ SCIMAGO | B8: อันดับ | C8: 10 | D8: 13 | E8: =10*100/13 -> 76.923077 | F8: อ้างอิงข้อมูลจากส่วนกลาง | G8: พิจารณาจากรายงานผลการดำเนินงานที่สนับสนุนเป้าหมายของมหาวิทยาลัย เพื่อเข้าสู่การจัดอันดับ SCIMAGO ตามเป้าหมายที่กำหนด
A9: 1.1.3 ผลการจัดอันดับ QS ด้านเกษตรและป่าไม้ | B9: อันดับ | C9: อันดับที่ 401-450 ของโลก | D9: 401 | E9: 100 | F9: อ้างอิงข้อมูลจากส่วนกลาง | G9: พิจารณาจากรายงานผลการดำเนินงานที่สนับสนุนเป้าหมายของมหาวิทยาลัย เพื่อเข้าสู่การจัดอันดับ QS ด้านเกษตรและป่าไม้ ตามเป้าหมายที่กำหนด
A10: 1.1.4 ความสำเร็จในการร่วมสนับสนุนและขับเคลื่อนการดำเนินงานเพื่อเข้ารับการจัดอันดับ SDGs | B10: ระดับ | C10: 5 | D10: 0 | E10: 0 | F10: ยังไม่มีผลการดำเนินงาน | G10: พิจารณาจากการประเมินความสำเร็จตามกระบวนการ - มีการวิเคราะห์ข้อมูลที่เกี่ยวข้อง (1 คะแนน) - มีการวางแผนและกำหนดแนวทางการขับเคลื่อนการดำเนินงาน (1 คะแนน) - มีการจัดกิจกรรมที่เกี่ยวข้องอย่างน้อย 2 กิจกรรม โดยหนึ่งกิจกรรมต้องเกี่ยวข้องกับ SDG ที่รับผิดชอบ (1 คะแนน) - มีการรายงานผลการดำเนินงานต่อคณะกรรมการขับเคลื่อนการจัดอันดับม.สู่ความยั่งยืน (1 คะแนน) - มีการรายงานผลเข้าสู่ระบบรายงานผลกิจกรรมที่สอดคล้องกับ SDGs (1 คะแนน)
A11: 1.1.5. ความสำเร็จในการสนับสนุนมหาวิทยาลัยในการขับเคลื่อนนโยบาย Green U และ Green Office) | B11: ระดับ | C11: 3 | D11: 0 | E11: 0 | F11: ยังไม่มีผลการดำเนินงาน | G11: พิจารณาจากเกณฑ์การประเมินผลการดำเนินงานตามมติที่ประชุมคณะกรรมการขับเคลื่อนยุทธศาสตร์การเป็นมหาวิทยาลัยสีเขียว (Green University) หรือ Green Office
A12: เป้าประสงค์ที่ 1.2 เป็นมหาวิทยาลัยที่เป็นเลิศด้านเกษตรอัจฉริยะเพื่อสุขภาวะที่ดี
A13: 1.2.1 ความสำเร็จของยุทธศาสตร์เกษตรอินทรีย์ (Organic University) | B13: ร้อยละ | C13: 90 | D13: 22.22 | E13: =22.22*100/C13 -> 24.688889 | F13: อ้างอิงข้อมูลจากส่วนกลาง | G13: พิจารณาจากผลการดำเนินงานการร่วมขับเคลื่อนกิจกรรมสำคัญที่จะขับเคลื่อนการดำเนินงานในปีงบประมาณ พ.ศ. 2569 ดังนี้ 1.ผลงานการเรียนการสอนด้านเกษตรอินทรีย์ 1.1 หลักสูตรด้านเกษตรอินทรีย์(Degree/non-degree) ที่เปิดสอน ในปีงบประมาณ 2569) 1.2 จำนวณบัณฑิต หรือ ผู้จบหลักสูตรด้านเกษตรอินทรีย์ 2.ผลงานวิจัยด้านเกษตรอินทรีย์ 2.1 จำนวนงบประมาณสนับสนุนงานวิจัยด้านเกษตรอินทรีย์ 3. ผลงานบริการวิชาการด้านเกษตรอินทรีย์ 3.1 จำนวนองค์ความรู้/ข้อเสนอเชิงนโยบาย ด้านเกษตรอินทรีย์ที่ได้รับการใช้ประโยชน์สู่สาธารณะ/ชุมชน 3.2 เครือข่ายเกษตรกร หรือผู้ประกอบการด้านเกษตรอินทรีย์ 4. ด้านภาพลักษณ์เกษตรอินทรีย์แม่โจ้และการบริหารจัดการ 4.1 การพัฒนาฐานข้อมูลเกษตรอินทรีย์ มหาวิทยาลัยแม่โจ้ 4.2 ความสำเร็จของ Maejo PGS 4.3 ความสำเร็จของกาด 2477 4.4 จำนวนพื้นที่อินทรีย์ภายในมหาวิทยาลัยที่ผ่านการรับรอง-
A14: 1.2.2 ความสำเร็จของการดำเนินงานด้านเกษตรอัจฉริยะ (Intelligent Agriculture) | B14: ร้อยละ | C14: 90 | D14: 16.67 | E14: =D14*100/C14 -> 18.522222 | F14: อ้างอิงข้อมูลจากส่วนกลาง | G14: พิจารณาจากผลการดำเนินงานกิจกรรมสำคัญที่จะขับเคลื่อนการดำเนินงานในปีงบประมาณ พ.ศ. 2569 ดังนี้ 1.ผลงานการเรียนการสอนด้านเกษตรอัจฉริยะ 1.1 หลักสูตรด้านเกษตรอัจฉริยะ (Degree/non-degree) ที่เปิดสอน (ในปีงบประมาณ 2569) 1.2 จำนวณบัณฑิต หรือ ผู้จบหลักสูตรด้านเกษตรอัจฉริยะ 2.ผลงานวิจัยด้านเกษตรอัจฉริยะ 2.1 จำนวนโครงการวิจัยด้านเกษตรอัจฉริยะ 3. ผลงานการบริการวิชาการด้านเกษตรอัจฉริยะ 3.1 จำนวนเทคโนโลยี นวัตกรรมและกระบวนการเกษตรสมัยใหม่และเกษตรอัจฉริยะที่ได้รับการพัฒนาต่อยอดกับชุมชน สังคม หรือพาณิชย์ 3.2 จำนวนเครือข่ายความร่วมมือและจำนวนเครือข่ายที่ได้รับการพัฒนาและขยายความร่วมมือกับกลุ่มผู้ใช้นวัตกรรมเกษตรสมัยใหม่และเกษตรอัจฉริยะ 4. ด้านภาพลักษณ์เกษตรอัจฉริยะแม่โจ้ 4.1 จำนวนพื้นที่/ศูนย์ถ่ายทอดนวัตกรรม/แหล่งเรียนรู้ และฟาร์มเกษตรสมัยใหม่และเกษตรอัจฉริยะภายในมหาวิทยาลัย
A15: 2.1.3 ความสำเร็จในการพัฒนานักศึกษาสู่การเป็นผู้มีสุขภาวะที่ดี | B15: ร้อยละ | C15: 90 | D15: 48.57 | E15: =D15*100/C15 -> 53.966667 | F15: รอข้อมูลจากส่วนกลาง | G15: พิจารณาจากความสำเร็จของการบรรลุเป้าหมายตามตัวชี้วัดและกิจกรรมโครงการที่กำหนดดังนี้ กิจกรรมที่จะดำเนินการ 1. กิจกรรมกวดขันวินัยและสร้างจิตสำนึกวินัยจราจร (ศึกษาวิจัย) (ZT) 2. การสำรวจสุขภาพจิต (แบบสำรวจสุขภาพจิต)นักศึกษาและบุคลากร (HP) 3. กิจกรรมส่งเสริมสุขภาพให้แก่นักศึกษาและบุคลากรในกลุ่มเสี่ยงจากข้อมูลการตรวจสุขภาพประจำปีบุคลกรและข้อมูลรายงานสุขภาพนักศึกษา(HP) 4. การดำเนินงานเพื่อพัฒนานักศึกษาสู่การเป็นผู้มีสุขภาวะที่ดีของแต่ละส่วนงาน
A16: ประเด็นยุทธศาสตร์ที่ 2. การขับเคลื่อนผลการดำเนินงานตามพันธกิจหลัก (Driving Mission - Driven Performance)
A17: เป้าประสงค์ที่ 2.1 ผลิตบัณฑิตและพัฒนานักศึกษาที่ก้าวทันต่อโลกสมัยใหม่และเป็นนักปฏิบัติที่เชี่ยวชาญ
A18: 2.1.1 จำนวนนักศึกษาใหม่ระดับปริญญาตรี | B18: คน | C18: 130 | D18: N/A | E18: N/A | F18: รอข้อมูลนักศึกษาใหม่ระดับปริญญาตรี ปีการศึกษา 2569 | G18: พิจารณาจากการนับจำนวนนักศึกษารับเข้าระดับปริญญาตรี (ทั้งภาคปกติและสมทบ) ลงทะเบียนเข้าศึกษาชั้นปีที่1 ในหลักสูตรทุกประเภท ประจำปีการศึกษา 2569
A19: 2.1.2 ร้อยละของผู้สำเร็จการศึกษาภายในระยะเวลาของหลักสูตร | B19: ร้อยละ | C19: 80 | D19: 0 | E19: =IF((D19*100)/C19>=100,100,(D19*100)/C19) -> 0 | F19: ยังไม่มีผลการดำเนินงาน | G19: พิจารณาจากจำนวนนักศึกษาชั้นปีสุดท้ายระดับปริญญาตรี (ภาคปกติ) หลักสูตร 4 ปีและ 5 ปี สำเร็จการศึกษาในปีการศึกษา 2569 / จำนวนนักศึกษาหลักสูตร 4 ปีและ 5 ปี ชั้นปีสุดท้ายทั้งหมด) x 100
A20: 2.1.3 ร้อยละของบัณฑิตที่มีงานทำหรือประกอบอาชีพอิสระภายใน 1 ปี | B20: ร้อยละ | C20: 80 | D20: 74.29 | E20: =IF((D20*100)/C20>=100,100,(D20*100)/C20) -> 92.8625 | F20: มีบัณฑิตตอบแบบสอบถาม จำนวน 91 คน มีงานทำ จำนวน 76 คน | G20: พิจารณาจากจำนวนบัณฑิตระดับปริญญาตรีที่สำเร็จในปีการศึกษา 2567 ที่ได้งานทำหรือประกอบอาชีพอิสระภายใน 1 ปี / จำนวนบัณฑิตที่ตอบแบบสำรวจทั้งหมด) X 100
A21: 2.1.4 ความพึงพอใจผู้ใช้บัณฑิต | B21: ค่าเฉลี่ย | C21: 4.4 | D21: N/A | E21: N/A | F21: รอข้อมูลจากส่วนกลาง | G21: พิจารณาจากค่าเฉลี่ยผลการสำรวจความพึงพอใจของผู้ใช้บัณฑิต ประจำปีการศึกษา 2567 จากระบบความพึงพอใจของผู้ใช้บัณฑิต
A22: 2.1.5 รายได้เริ่มต้นเฉลี่ยต่อเดือนของบัณฑิตระดับปริญญาตรี | B22: บาท | C22: 15000 | D22: 15840 | E22: =IF((D22*100)/C22>=100,100,(D22*100)/C22) -> 100 | F22: อ้างอิงข้อมูลจากส่วนกลาง | G22: พิจารณาจากจำนวนรายได้เฉลี่ยต่อเดือนเริ่มต้นของบัณฑิตปริญญาตรีที่สำเร็จการศึกษา ในปีการศึกษา 2567
A23: 2.1.6ค่าฐานนิยม (Mode) ผลการประเมินระดับหลักสูตร | B23: ค่าเฉลี่ย | C23: 3 | D23: N/A | E23: N/A | F23: รอผลการประเมินของหลักสูตร | G23: พิจารณาจากค่าฐานนิยม (Mode) จากผลการประเมินคุณภาพการศึกษาระดับหลักสูตรตามเกณฑ์ AUN-QA ของทุกหลักสูตรในปีการศึกษา 2568 **ข้อมูลอ้างอิงจากระบบรายงานผลการประเมินคุณภาพการศึกษา (QA-Report)
A24: 2.1.7 จำนวนรายวิชาเรียนรู้ตลอดชีวิต | B24: รายวิชา | C24: 2 | D24: 2 | E24: =IF((D24*100)/C24>=100,100,(D24*100)/C24) -> 100 | F24: 1. นวัตกรรมปลาน้ำจืดสำหรับผู้ประกอบการ โดยรองศาสตราจารย์ ดร.เกรียงศักดิ์ เม่งอำพัน มีจำนวนผู้ลงทะเบียนเรียน 192 คน สำเร็จการศึกษา 44 คน 2. หลักสูตรนวัตกรรมการเพิ่มมูลค่าผลผลิตทางการเกษตรเพื่อ ขับเคลื่อนเศรษฐกิจ BCG (กลุ่มอุตสาหกรรมเกษตร สมัยใหม่และการแปรรูปอาหาร) (โครงการบัณฑิตพันธุ์ใหม่ฯ) | G24: พิจารณาจากการนับจำนวนรายวิชาเรียนรู้ตลอดชีวิตที่คณะกรรมการวิชาการรับทราบ และมีการเปิดรับนักศึกษาในปีงบประมาณ พ.ศ. 2569
A25: 2.1.8 จำนวนรางวัลที่นักศึกษา บุคลากร ศิษย์เก่าหรือส่วนงาน ได้รับในระดับชาติ หรือนานาชาติ | B25: รางวัล | C25: 5 | D25: 12 | E25: =IF((D25*100)/C25>=100,100,(D25*100)/C25) -> 100 | F25: คณะมีจำนวนรางวัลที่นักศึกษา บุคลากร ศิษย์เก่า หรือส่วนงาน ได้รับในระดับชาติ หรือนานาชาติ จำนวน 12 รางวัล ได้แก่ 1. รางวัล Best Poster Presentation Award จากผลงาน เรื่อง Preliminary Study on Semantic Segmentation of Head, Tail, Fins, and Body of Nile Tilapia Using Deep Convolutional Neural Networks with Transfer Learning ของ รศ.ดร.นิสรา กิจเจริญ 2. รางวัลการนำเสนอผลงานภาคบรรยายระดับดีมาก เรื่อง การเปรียบเทียบสูตรอาหารที่เหมาะสมในการเพาะเลี้ยงคลอเรลล่าของ นายคณัสนันท์ จันต๊ะมงคล 3. รางวัลการนำเสนอผลงานภาคบรรยายระดับดีมาก เรื่อง แนวทางการเสริมสร้างศักยภาพธุรกิจปลาดุกในห่วงโซ่การผลิตพื้นที่อำเภอสันทราย จังหวัดเชียงใหม่ ของ นายชิณเสฏฐ์ เอี่ยมเมือง 4. รางวัลการนำเสนอผลงานภาคบรรยายระดับดี เรื่อง การพัฒนาสูตรอาหารปลานิลอินทรีย์จากวัตถุดินอินทรีย์เสริมชีวมวลไบโอฟลอค : การประเมินประสิทธิภาพการเจริญเติบโตและต้นทุนการผลิต ของ น.ส.พิชญาภา พิทักษ์วัชรีกุล 5. รางวัลการนำเสนอผลงานภาคบรรยายระดับดีมาก เรื่อง ประสิทธิภาพการเจริญเติบโตของปลานิลที่เลี้ยงด้วยอาหารผสมกากมะพร้าวหมักที่ระดับแตกต่างกัน ของ น.ส.พุทธิดา สมบูรณ์ชัย 6. รางวัลการนำเสนอผลงานภาคโปสเตอร์ระดับดีมาก เรื่อง ผลของชนิดพริก วิธีการทำแห้ง ชนิดของบรรจุภัณฑ์ และวิธีการฆ่าเชื้อที่มีต่อคุณลักษณะของน้ำพริกน้ำปู ของ น.ส.เพ็ญนภา ชูเยาว์ 7. รางวัลการนำเสนอผลงานภาคบรรยายระดับดีเยี่ยม เรื่อง การศึกษาทางอนุกรมวิธาน และการค้นพบปลาค้อชนิดใหม่จากลำน้ำเข็ก อำเภอเขาค้อ จังหวัดเพชรบูรณ์ ของ นายภัคพล ชุมศิลป์ 8. รางวัลการนำเสนอผลงานภาคโปสเตอร์ระดับดีเยี่ยม เรื่อง การพัฒนาผลิตภัณฑ์ปลาบึกทอดกรอบจากวัตถุดิบที่ผ่านการบ่มแบบเปียกโดยการคัดกรองปัจจัยด้วยการออกแบบการทดลองแบบ Plackett-Burman ของ อ.ดร.นงพงา แสงเจริญ 9. รางวัลเชิดชูเกียรติ "คนดีศรีเกษตร" ของ น.ส.เพ็ญนภา ชูเยาว์ 10. รางวัลเหรียญทอง "ทักษะการบรรจุพันธุ์ลูกปลา" 11. รางวัลเหรียญทอง "การประกวดโมเดลธุรกิจนวัตกรรมการเกษตร" 12. รางวัลเหรียญทอง "ทักษะการทอดแห" | G25: พิจารณาจากการนับจำนวนรางวัลจำนวนรางวัลที่นักศึกษา บุคลากร ศิษย์เก่า หรือส่วนงาน/หน่วยงานได้รับในระดับชาติ/นานาชาติ ในปีงบประมาณ พ.ศ. 2569
A26: 2.1.9 ร้อยละของนักศึกษาชั้นปีสุดท้ายที่ผ่านกระบวนการ พัฒนาพัฒนาให้เป็นพลเมืองโลก ด้วยกระบวนการทักษะในศตวรรษที่ 21 | B26: ร้อยละ | C26: 90 | D26: 100 | E26: =IF((D26*100)/C26>=100,100,(D26*100)/C26) -> 100 | F26: ร้อยละของนักศึกษาชั้นปีสุดท้ายที่ผ่านกระบวนการ พัฒนาพัฒนาให้เป็นพลเมืองโลก ด้วยกระบวนการทักษะในศตวรรษที่ 21 ร้อยละ 100 | G26: พิจารณาจากจำนวนนักศึกษาชั้นปีสุดท้ายที่ได้รับการพัฒนาตามกระบวนการพัฒนาทักษะการเรียนรู้ในศตวรรษที่ 21 / จำนวนนักศึกษาชั้นปีสุดท้ายทั้งหมด) x 100
A27: เป้าประสงค์ที่ 2.2 สร้างผลงานวิจัย เทคโนโลยีและนวัตกรรม ที่มีการบูรณาการศาสตร์ โดยใช้เกษตรเป็นรากฐาน และได้รับการยอมรับในระดับชาติและนานาชาติ
A28: 2.2.1 จำนวนเงินวิจัยด้านวิทยาศาสตร์และเทคโนโลยี | B28: บาท | C28: 5167959 | D28: 9088219 | E28: =IF((D28*100)/C28>=100,100,(D28*100)/C28) -> 100 | F28: ในปีงบประมาณ 2569 คณะฯ มีเงินสนับสนุนงานวิจัย จำนวน 9,088,219 บาท โดยแบ่งออกเป็นแหล่งทุนงานวิจัยภายใน จำนวน 2,034,440 บาท และเป็นทุนงานวิจัยจากภายนอก จำนวน 7,053,779 บาท ต่ออาจารย์ประจำที่ปฏิบัติงานจริง จำนวน 15 คน ดังนั้น จึงคิดเป็นจำนวน 605,881.27 บาท ต่อคน | G28: พิจารณาจากจำนวนเงินสนับสนุนโครงการวิจัยจากทุกแหล่งงบประมาณ (งบประมาณแผ่นดินและงบประมาณจากแหล่งอื่น) ที่อาจารย์/นักวิจัยประจำได้รับ ที่ได้ขึ้นทะเบียนงานวิจัยที่สำนักวิจัยฯ และบันทึกเข้าสู่ฐานข้อมูลงานวิจัยในระบบ ERP
A29: 2.2.2 ร้อยละของอาจารย์และนักวิจัยประจำที่มีผลงานวิจัย | B29: ร้อยละ | C29: 70 | D29: 60 | E29: =IF((D29*100)/C29>=100,100,(D29*100)/C29) -> 85.714286 | F29: อาจารย์ประจำที่มีงานวิจัย จำนวน 9 คน ต่อจำนวนอาจารย์ประจำที่ปฏิบัติงานจริง 15 คน คิดเป็นร้อยละ 60 โดยมีรายชื่ออาจารย์ที่ได้รับทุน ดังนี้ 1. ผศ.ดร.สุดาพร ตงศิริ 2. รศ.ดร.ชนกันต์ จิตมนัส 3. อ.ดร.โดม อดุลย์สุข 4. อ.ดร.วาธิณี อินทรพงษ์นุวัฒน์ 5. รศ.ดร.จงกล พรมยะ 6. อ.ดร.ขจรเกียรติ์ ศรีนวลสม 7. อ.ดร.นงพงา แสงเจริญ 8. รศ.ดร.ดวงพร อมรเลิศพิศาล 9. ผศ.ดร.ดารชาต์ เทียมเมือง | G29: พิจารณาจากจำนวนอาจารย์และนักวิจัยประจำที่มีผลงานวิจัยนับเฉพาะที่เป็นหัวหน้าโครงการหรือมีความรับผิดชอบในโครงการวิจัยนั้นๆ ในปีงบประมาณ พ.ศ. 2569
A30: 2.2.3 จำนวนครั้งในการผลงานวิจัยหรืองานสร้างสรรค์ที่นำไปใช้ประโยชน์ | B30: ครั้ง | C30: 3 | D30: 8 | E30: =IF((D30*100)/C30>=100,100,(D30*100)/C30) -> 100 | F30: คณะฯ มีการนำผลงานวิจัยหรืองานสร้างสรรค์ไปใช้ประโยชน์ จำนวน 8 ครั้ง ได้แก่ 1. นำงานวิจัย เรื่อง ศึกษาประสิทธิภาพระบบเลี้ยงปลาดุกและปลูกผักในบ้านอัจฉริยะ ไปใช้ประโยชน์แก่ภาควิชาสัตวศาสตร์และสัตว์น้ำ คณะเกษตรศาสตร์ มหาวิทยาลัย เชียงใหม่ 2. นำงานวิจัย เรื่อง ศึกษาประสิทธิภาพระบบเลี้ยงปลาดุกและปลูกผักในบ้านอัจฉริยะ ไปใช้ประโยชน์แก่คณะเทคโนโลยีการเกษตร มหาวิทยาลัยราชภัฏเชียงใหม่ 3. นำงานวิจัย เรื่อง โครงการการพัฒนาผลิตภัณฑ์ซินไบโอติกส์ร่วมกับวัสดุเหลือทิ้งทางการเกษตร เพื่อลดการใช้ยาปฏิชีวนะในสัตว์น้ำ ไปใช้ประโยชน์แก่บริษัท อุตสาหกรรม เทคโนโลยี ชีวภาพ (ประเทศไทย) จำกัด 4. นำงานวิจัย เรื่อง ประสิทธิภาพของชีวภัณฑ์ shrimp premix และ MEX1 ต่อสุขภาพและผลผลิตของกุ้งเศรษฐกิจ ไปใช้ประโยชน์แก่บริษัท อุตสาหกรรม เทคโนโลยี ชีวภาพ (ประเทศไทย) จำกัด 5. นำงานวิจัย เรื่อง ประสิทธิภาพของชีวภัณฑ์ fish premix และ THEPTM1 ต่อการเจริญเติบโตและคุณภาพของปลานิล ไปใช้ประโยชน์แก่บริษัท อุตสาหกรรม เทคโนโลยี ชีวภาพ (ประเทศไทย) จำกัด 6. นำงานวิจัย เรื่อง การผลิตสารสกัดจากส่วนดอกและใบดาหลา 2 ชนิด ไปใช้ประโยชน์แก่วิสาหกิจชุมชนมั่นคง มั่งคั่ง ยั่งยืน 7. นำงานวิจัย เรื่อง การขยายสเกลการผลิตสารเสริมโปรตีนปลาไฮโดรไลเสตสำหรับเป็นสารเสริมกระตุ้นการกินในสัตว์เลี้ยง ระดับกึ่งอุตสาหกรรม ไปใช้ประโยชน์แก่บริษัท นิวทรีชั่น เอสซี จำกัด (มหาชน) 8. นำงานวิจัย เรื่อง การขยายสเกลการผลิตและทดสอบทางคลินิกของผลิตภัณฑ์มูลค่าเพิ่มจากส่วนเหลือใช้การแปรรูปปลาลูกผสมบึกสยามแม่โจ้ ไปใช้ประโยชน์แก่บริษัท เซนทอล จำกัด | G30: พิจารณาจากจำนวนครั้งในการนำผลงานวิจัยหรืองานสร้างสรรค์ของอาจารย์/นักวิจัยประจำที่มีการนำมาใช้ประโยชน์ในปีงบประมาณ พ.ศ. 2569
A31: 2.2.4 ร้อยละของผลงานวิจัยที่ได้รับการตีพิมพ์เผยแพร่ตามเกณฑ์การเผยแพร่ผลงานวิชาการของ กพอ. | B31: ร้อยละ | C31: 50 | D31: 106.25 | E31: =IF((D31*100)/C31>=100,100,(D31*100)/C31) -> 100 | F31: งานวิจัยหรืองานสร้างสรรค์ที่ได้รับการตีพิมพ์หรือเผยแพร่ จำนวน 17 เรื่อง คิดคะแนนถ่วงน้ำหนัก เท่ากับ 16.00 ต่อจำนวนอาจารย์ประจำและลาศึกษาต่อ จำนวน 16 คน คิดเป็นร้อยละ 106.25 - ฐานข้อมูล TCI กลุ่ม 2 จำนวน 1 เรื่อง - ฐานข้อมูล TCI กลุ่ม 1 จำนวน 3 เรื่อง - ฐานข้อมูลระดับนานาชาติ 13 เรื่อง | G31: พิจารณาจากจำนวนผลงานวิจัยหรืองานสร้างสรรค์ที่ได้รับการตีพิมพ์ระดับชาติหรือนานาชาติ / จำนวนอาจารย์และนักวิจัยประจำทั้งหมด) x 100
A32: 2.2.5 ร้อยละของบทความวิจัยที่ได้รับการอ้างอิง (Citation) ต่อจำนวนอาจารย์ประจำทั้งหมด | B32: ร้อยละ | C32: 110 | D32: 1112.5 | E32: =IF((D32*100)/C32>=100,100,(D32*100)/C32) -> 100 | F32: ในปีงบประมาณ 2569 คณะฯ มีผลการดำเนินงานด้านบทความวิจัยที่ได้รับการอ้างอิง (Citation) ใน Refereed journal หรือในฐานข้อมูลระดับนานาชาติ จำนวน 178 เรื่อง (ข้อมูลวันที่ 27 มีนาคม 2569) ต่ออาจารย์ประจำที่ปฏิบัติงานจริงและลาศึกษาต่อ จำนวน 16 คน คิดเป็นร้อยละ 1,112.50 | G32: พิจารณาจากบทความวิจัยหรืองานสร้างสรรค์ที่ได้รับการอ้างอิง (Citation) ใน (Refereed journal หรือในฐานข้อมูลระดับนานาชาติ / จำนวนอาจารย์และนักวิจัยประจำทั้งหมด) x 100* นับอาจารย์ลาศึกษาต่อ
A33: 2.2.6 จำนวนผลงานวิจัยที่ยื่นขอจดสิทธิบัตร/อนุสิทธิบัตร/บัญชีนวัตกรรม/นวัตกรรมต้นแบบ | B33: ผลงาน | C33: 2 | D33: 1 | E33: =IF((D33*100)/C33>=100,100,(D33*100)/C33) -> 50 | F33: ผลงานวิจัยหรืองานสร้างสรรค์ของอาจารย์ประจำที่เสนอขอรับการจดทะเบียนสิทธิบัตร/อนุสิทธิบัตร จำนวน 6 ผลงาน ได้แก่ 1. ยื่นขอการจดทะเบียนอนุสิทธิบัตร สูตรขนมเลียผสมซินไบโอติกสำหรับแมว โดย รศ.ดร.ดวงพร อมรเลิศพิศาล | G33: พิจารณาจากการนับจำนวนผลงานวิจัยที่ได้ยื่นขอจดสิทธิบัตร/อนุสิทธิบัตร/บัญชีนวัตกรรม/นวัตกรรมต้นแบบ
A34: 2.2.7 ร้อยละของผลงานวิชาการที่เสนอขอรับการจดลิขสิทธิ์ต่ออาจารย์ประจำ | B34: ร้อยละ | C34: 60 | D34: 18.75 | E34: =IF((D34*100)/C34>=100,100,(D34*100)/C34) -> 31.25 | F34: ในปีงบประมาณ 2569 คณะฯ มีผลงานวิชาการที่เสนอขอรับการจดลิขสิทธิ์ จำนวน 3 เรื่อง ต่อจำนวนอาจารย์ประจำทั้งหมด 16 คน คิดเป็นร้อยละ 18.75 | G34: พิจารณาจากจำนวนผลงานวิชาการที่เสนอขอรับการจดลิขสิทธิ์และ/หรือได้รับรองคุณภาพจากหน่วยงานที่เชื่อถือได้ ภายในปีงบประมาณ พ.ศ. 2569 ต่อจำนวนอาจารย์ประจำทั้งหมด
A35: 2.2.8 จำนวนองค์ความรู้งานวิจัยเพื่อพัฒนาผู้เรียน | B35: เรื่อง | C35: 10 | D35: 15 | E35: =IF((D35*100)/C35>=100,100,(D35*100)/C35) -> 100 | F35: มีการนำองค์ความรู้งานวิจัยมาประยุกต์ใช้ในการเรียนการสอน เพื่อพัฒนาผู้เรียน จำนวน 15 เรื่อง | G35: พิจารณาจากจำนวนองค์ความรู้งานวิจัยที่นำมาสู่การพัฒนาผู้เรียน ในปีงบประมาณ พ.ศ. 2569
A36: เป้าประสงค์ที่ 2.3 ให้บริการวิชาการเพื่อเป็นที่ยอมรับจากสังคม ชุมชน และประเทศ ด้วยศาสตร์ทางด้านการเกษตร
A37: 2.3.1 จำนวนงบประมาณบริการวิชาการ | B37: บาท | C37: 745000 | D37: 745000 | E37: =IF((D37*100)/C37>=100,100,(D37*100)/C37) -> 100 | F37: มีจำนวน 10 โครงการ | G37: พิจารณาจากการนับจำนวนงบประมาณบริการวิชาการจากทุกแหล่งทุน ในปีงบประมาณ พ.ศ. 2569
A38: 2.3.2 ผลกระทบด้านเศรษฐกิจ สังคม และคุณภาพชีวิตของชุมชนจากการบริการวิชาการ | B38: ค่าเฉลี่ย | C38: 4 | D38: N/A | E38: N/A | F38: รอผลประเมินเมื่อสิ้นสุดการจัดทำโครงการ | G38: พิจารณาจากค่าเฉลี่ยผลการสำรวจผลกระทบด้านเศรษฐกิจ สังคม และคุณภาพชีวิตของชุมชนเป้าหมาย ที่เกิดจากโครงการบริการวิชาการของมหาวิทยาลัยและส่วนงาน
A39: 2.3.3 ระดับความสำเร็จของการบูรณาการผลงานบริการวิชาการสู่พันธกิจอื่น | B39: ระดับ | C39: 5 | D39: N/A | E39: N/A | F39: รอผลการดำเนินงานเมื่อสิ้นสุดการจัดทำโครงการ | G39: พิจารณาจากจำนวนผลการนำความรู้และประสบการณ์จากการให้บริการวิชาการมาใช้ในการพัฒนาการเรียนการสอนและ/หรือการวิจัยต่อจำนวนโครงการบริการวิชาในแผนปฏิบัติการประจำปีงบประมาณ พ.ศ. 2569 โดยเทียบบัญญัติไตรยางศ์กำหนดร้อยละ 30 เท่ากับ 5 คะแนน
A40: เป้าประสงค์ที่ 2.4 เป็นแหล่งเรียนรู้ด้านศิลปวัฒนธรรมเกษตรและสิ่งแวดล้อม และสร้างสรรค์นวัตกรรมด้านทุนทางวัฒนธรรม
A41: 2.4.1 ความสำเร็จของแผนทำนุบำรุงศิลปวัฒนธรรม | B41: ร้อยละ | C41: 80 | D41: N/A | E41: N/A | F41: ยังไม่มีผลการดำเนินงาน | G41: พิจารณาจากผลการดำเนินงานตามตัวชี้วัดในแผนทำนุบำรุงศิลปวัฒนธรรม ประจำปีงบประมาณ พ.ศ. 2569
...

Sheet สรุป 6 เดือน 69
A1: สรุปร้อยละความสำเร็จตัวชี้วัดตามตัวชี้วัดตามแผนพัฒนาการศึกษา ระยะที่ 13 (พ.ศ.2565 - 2569) และแผนปฏิบัติการ ประจำปีงบประมาณ พ.ศ. 2569
A2: คณะเทคโนโลยีการประมงและทรัพยากรทางน้ำ รอบ 6 เดือน (1 ตุลาคม 2568 - 31 มีนาคม 2569)
A3: ประเด็นยุทธศาสตร์ | B3: จำนวนตัวชี้วัด | F3: ร้อยละความสำเร็จ ตามเป้าหมายเฉลี่ย | G3: ปัญหา/อุปสรรค และแนวทางปรับปรุง ผลการดำเนินในแต่ละประเด็นยุทธศาสตร์
B4: ผลการดำเนินงาน รอบ 6 เดือน
B5: รวม | C5: บรรลุเป้าหมาย | D5: ไม่บรรลุเป้าหมาย | E5: N/A | F5: รอบ 6 เดือน
A6: ประเด็นยุทธศาสตร์ที่ 1 (Proactive Strategy toward Inter IWA) | B6: =SUM(C6:E6) -> 8 | C6: 2 | D6: 6 | E6: 0 | F6: =AVERAGE('ตัวชี้วัด 69 (6 เดือน)'!E7:E11,'ตัวชี้วัด 69 (6 เดือน)'!E13:E15) -> 46.762607
A7: ประเด็นยุทธศาสตร์ที่ 2 การขับเคลื่อนผลการดำเนินงานตามพันธกิจหลัก | B7: =SUM(C7:E7) -> 16 | C7: =SUM(C8:C11) -> 10 | D7: 0 | E7: =SUM(E8:E11) -> 6 | F7: =AVERAGE('ตัวชี้วัด 69 (6 เดือน)'!E19,'ตัวชี้วัด 69 (6 เดือน)'!E20,'ตัวชี้วัด 69 (6 เดือน)'!E22,'ตัวชี้วัด 69 (6 เดือน)'!E24,'ตัวชี้วัด 69 (6 เดือน)'!E25,'ตัวชี้วัด 69 (6 เดือน)'!E26,'ตัวชี้วัด 69 (6 เดือน)'!E28,'ตัวชี้วัด 69 (6 เดือน)'!E29,'ตัวชี้วัด 69 (6 เดือน)'!E30,'ตัวชี้วัด 69 (6 เดือน)'!E31,'ตัวชี้วัด 69 (6 เดือน)'!E32,'ตัวชี้วัด 69 (6 เดือน)'!E33,'ตัวชี้วัด 69 (6 เดือน)'!E34,'ตัวชี้วัด 69 (6 เดือน)'!E35,'ตัวชี้วัด 69 (6 เดือน)'!E37,'ตัวชี้วัด 69 (6 เดือน)'!E42) -> 78.739174
A8: - ด้านผลิตบัณฑิต | B8: =SUM(C8:E8) -> 9 | C8: 4 | D8: 2 | E8: 3 | F8: =AVERAGE('ตัวชี้วัด 69 (6 เดือน)'!E19,'ตัวชี้วัด 69 (6 เดือน)'!E20,'ตัวชี้วัด 69 (6 เดือน)'!E22,'ตัวชี้วัด 69 (6 เดือน)'!E24,'ตัวชี้วัด 69 (6 เดือน)'!E25,'ตัวชี้วัด 69 (6 เดือน)'!E26) -> 82.14375
A9: - ด้านวิจัยและนวัตกรรม | B9: =SUM(C9:E9) -> 8 | C9: 5 | D9: 3 | E9: 0 | F9: =AVERAGE('ตัวชี้วัด 69 (6 เดือน)'!E28,'ตัวชี้วัด 69 (6 เดือน)'!E29,'ตัวชี้วัด 69 (6 เดือน)'!E30,'ตัวชี้วัด 69 (6 เดือน)'!E31,'ตัวชี้วัด 69 (6 เดือน)'!E32,'ตัวชี้วัด 69 (6 เดือน)'!E33,'ตัวชี้วัด 69 (6 เดือน)'!E34,'ตัวชี้วัด 69 (6 เดือน)'!E35) -> 83.370536
A10: - ด้านบริการวิชาการแก่สังคม | B10: =SUM(C10:E10) -> 3 | C10: 1 | D10: 0 | E10: 2 | F10: =AVERAGE('ตัวชี้วัด 69 (6 เดือน)'!E37) -> 100
A11: - ด้านทำนุบำรุงศิลปวัฒนธรรม | B11: =SUM(C11:E11) -> 2 | C11: 0 | D11: 1 | E11: 1 | F11: =AVERAGE('ตัวชี้วัด 69 (6 เดือน)'!E42) -> 0
A12: ประเด็นยุทธศาสตร์ที่ 3 การขับเคลื่อนความเป็นนานาชาติ | B12: =SUM(C12:E12) -> 5 | C12: 0 | D12: 4 | E12: 1 | F12: =AVERAGE('ตัวชี้วัด 69 (6 เดือน)'!E45,'ตัวชี้วัด 69 (6 เดือน)'!E46,'ตัวชี้วัด 69 (6 เดือน)'!E48,'ตัวชี้วัด 69 (6 เดือน)'!E51) -> 52.5
A13: ประเด็นยุทธศาสตร์ที่ 4 การขับเคลื่อนสู่การเป็นมหาวิทยาลัยด้านการพัฒนาเทคโนโลยีและส่งเสริมการสร้างนวัตกรรม | B13: =SUM(C13:E13) -> 3 | C13: 1 | D13: 2 | E13: 0 | F13: =AVERAGE('ตัวชี้วัด 69 (6 เดือน)'!E56:E59) -> 60
A14: ประเด็นยุทธศาสตร์ที่ 5 การบริหารจัดการและการเสริมสร้างความมั่นคงทางการเงินอย่างยั่งยืน | B14: =SUM(C14:E14) -> 8 | C14: 3 | D14: 2 | E14: 3 | F14: =AVERAGE('ตัวชี้วัด 69 (6 เดือน)'!E66,'ตัวชี้วัด 69 (6 เดือน)'!E69,'ตัวชี้วัด 69 (6 เดือน)'!E70,'ตัวชี้วัด 69 (6 เดือน)'!E71,'ตัวชี้วัด 69 (6 เดือน)'!E73) -> 69.488286
A15: เฉลี่ยประเด็น 1-5 | B15: =B6+B7+B12+B13+B14 -> 40 | C15: =C6+C7+C12+C13+C14 -> 16 | D15: =D6+D7+D12+D13+D14 -> 14 | E15: =E6+E7+E12+E13+E14 -> 10 | F15: =AVERAGE('ตัวชี้วัด 69 (6 เดือน)'!E7,'ตัวชี้วัด 69 (6 เดือน)'!E8,'ตัวชี้วัด 69 (6 เดือน)'!E9,'ตัวชี้วัด 69 (6 เดือน)'!E10,'ตัวชี้วัด 69 (6 เดือน)'!E11,'ตัวชี้วัด 69 (6 เดือน)'!E13,'ตัวชี้วัด 69 (6 เดือน)'!E14,'ตัวชี้วัด 69 (6 เดือน)'!E15,'ตัวชี้วัด 69 (6 เดือน)'!E19,'ตัวชี้วัด 69 (6 เดือน)'!E20,'ตัวชี้วัด 69 (6 เดือน)'!E22,'ตัวชี้วัด 69 (6 เดือน)'!E24,'ตัวชี้วัด 69 (6 เดือน)'!E25,'ตัวชี้วัด 69 (6 เดือน)'!E26,'ตัวชี้วัด 69 (6 เดือน)'!E28,'ตัวชี้วัด 69 (6 เดือน)'!E29,'ตัวชี้วัด 69 (6 เดือน)'!E30,'ตัวชี้วัด 69 (6 เดือน)'!E31,'ตัวชี้วัด 69 (6 เดือน)'!E32,'ตัวชี้วัด 69 (6 เดือน)'!E33,'ตัวชี้วัด 69 (6 เดือน)'!E34,'ตัวชี้วัด 69 (6 เดือน)'!E35,'ตัวชี้วัด 69 (6 เดือน)'!E37,'ตัวชี้วัด 69 (6 เดือน)'!E42,'ตัวชี้วัด 69 (6 เดือน)'!E45,'ตัวชี้วัด 69 (6 เดือน)'!E46,'ตัวชี้วัด 69 (6 เดือน)'!E48,'ตัวชี้วัด 69 (6 เดือน)'!E51,'ตัวชี้วัด 69 (6 เดือน)'!E56,'ตัวชี้วัด 69 (6 เดือน)'!E57,'ตัวชี้วัด 69 (6 เดือน)'!E59,'ตัวชี้วัด 69 (6 เดือน)'!E66,'ตัวชี้วัด 69 (6 เดือน)'!E69,'ตัวชี้วัด 69 (6 เดือน)'!E70,'ตัวชี้วัด 69 (6 เดือน)'!E71,'ตัวชี้วัด 69 (6 เดือน)'!E73) -> 65.871363
A16: ระดับความสำเร็จ (คะแนนเต็ม 5) | F16: =F15*5/100 -> 3.2935682
C63: 5 | D63: 3

Sheet ตัวชี้วัด 69 (9 เดือน)
A2: รายงานผลการดำเนินงานตามตัวชี้วัดแผนพัฒนาการศึกษา ฉบับที่ 13 (พ.ศ.2566 - 2570) ฉบับปรับปรุง และแผนปฏิบัติการ ประจำปีงบประมาณ พ.ศ. 2569
A3: รอบ 9 เดือน (1 ตุลาคม 2568 - 30 มิถุนายน 2569) คณะเทคโนโลยีการประมงและทรัพยากรทางน้ำ มหาวิทยาลัยแม่โจ้
A4: ตัวชี้วัด | B4: หน่วยนับ | C4: เป้าหมาย ปีงบประมาณ 2569 | D4: ผลการดำเนินงาน | E4: ร้อยละ ความสำเร็จ | F4: รายละเอียดการดำเนินงาน / เอกสารอ้างอิง | G4: คำอธิบายเกณฑ์การประเมินตัวชี้วัด
A5: ประเด็นยุทธศาสตร์ที่ 1. การขับเคลื่อนยุทธศาสตร์มหาวิทยาลัยเชิงรุกสู่การเป็นมหาวิทยาลัยชั้นนำด้านเกษตรสุขภาวะในระดับนานาชาติ (Proactive Strategy toward Inter IWA)
A6: เป้าประสงค์ที่ 1.1 เป็นมหาวิทยาลัยชั้นนำด้านการเกษตรสุขภาวะในระดับนานาชาติ
A7: 1.1.1 ผลการจัดอันดับ World University Ranking (WUR) | B7: อันดับ | C7: อันดับที่ 1,201-1,500 ของโลก | D7: 1501 | E7: 100 | F7: อ้างอิงข้อมูลจากส่วนกลาง | G7: พิจารณาจากรายงานผลการดำเนินงานที่สนับสนุนเป้าหมายของมหาวิทยาลัย เพื่อเข้าสู่การจัดอันดับ World University Ranking (WUR)-
A8: 1.1.2 ผลการจัดอันดับ SCIMAGO | B8: อันดับ | C8: 10 | D8: 13 | E8: =10*100/13 -> 76.923077 | F8: อ้างอิงข้อมูลจากส่วนกลาง | G8: พิจารณาจากรายงานผลการดำเนินงานที่สนับสนุนเป้าหมายของมหาวิทยาลัย เพื่อเข้าสู่การจัดอันดับ SCIMAGO ตามเป้าหมายที่กำหนด
A9: 1.1.3 ผลการจัดอันดับ QS ด้านเกษตรและป่าไม้ | B9: อันดับ | C9: อันดับที่ 401-450 ของโลก | D9: 401 | E9: 100 | F9: อ้างอิงข้อมูลจากส่วนกลาง | G9: พิจารณาจากรายงานผลการดำเนินงานที่สนับสนุนเป้าหมายของมหาวิทยาลัย เพื่อเข้าสู่การจัดอันดับ QS ด้านเกษตรและป่าไม้ ตามเป้าหมายที่กำหนด
A10: 1.1.4 ความสำเร็จในการร่วมสนับสนุนและขับเคลื่อนการดำเนินงานเพื่อเข้ารับการจัดอันดับ SDGs | B10: ระดับ | C10: 5 | D10: 0 | E10: 0 | F10: ยังไม่มีผลการดำเนินงาน | G10: พิจารณาจากการประเมินความสำเร็จตามกระบวนการ - มีการวิเคราะห์ข้อมูลที่เกี่ยวข้อง (1 คะแนน) - มีการวางแผนและกำหนดแนวทางการขับเคลื่อนการดำเนินงาน (1 คะแนน) - มีการจัดกิจกรรมที่เกี่ยวข้องอย่างน้อย 2 กิจกรรม โดยหนึ่งกิจกรรมต้องเกี่ยวข้องกับ SDG ที่รับผิดชอบ (1 คะแนน) - มีการรายงานผลการดำเนินงานต่อคณะกรรมการขับเคลื่อนการจัดอันดับม.สู่ความยั่งยืน (1 คะแนน) - มีการรายงานผลเข้าสู่ระบบรายงานผลกิจกรรมที่สอดคล้องกับ SDGs (1 คะแนน)
A11: 1.1.5. ความสำเร็จในการสนับสนุนมหาวิทยาลัยในการขับเคลื่อนนโยบาย Green U และ Green Office) | B11: ระดับ | C11: 3 | D11: 0 | E11: 0 | F11: ยังไม่มีผลการดำเนินงาน | G11: พิจารณาจากเกณฑ์การประเมินผลการดำเนินงานตามมติที่ประชุมคณะกรรมการขับเคลื่อนยุทธศาสตร์การเป็นมหาวิทยาลัยสีเขียว (Green University) หรือ Green Office
A12: เป้าประสงค์ที่ 1.2 เป็นมหาวิทยาลัยที่เป็นเลิศด้านเกษตรอัจฉริยะเพื่อสุขภาวะที่ดี
A13: 1.2.1 ความสำเร็จของยุทธศาสตร์เกษตรอินทรีย์ (Organic University) | B13: ร้อยละ | C13: 90 | D13: 62.5 | E13: =D13*100/C13 -> 69.444444 | F13: อ้างอิงข้อมูลจากส่วนกลาง | G13: พิจารณาจากผลการดำเนินงานการร่วมขับเคลื่อนกิจกรรมสำคัญที่จะขับเคลื่อนการดำเนินงานในปีงบประมาณ พ.ศ. 2569 ดังนี้ 1.ผลงานการเรียนการสอนด้านเกษตรอินทรีย์ 1.1 หลักสูตรด้านเกษตรอินทรีย์(Degree/non-degree) ที่เปิดสอน ในปีงบประมาณ 2569) 1.2 จำนวณบัณฑิต หรือ ผู้จบหลักสูตรด้านเกษตรอินทรีย์ 2.ผลงานวิจัยด้านเกษตรอินทรีย์ 2.1 จำนวนงบประมาณสนับสนุนงานวิจัยด้านเกษตรอินทรีย์ 3. ผลงานบริการวิชาการด้านเกษตรอินทรีย์ 3.1 จำนวนองค์ความรู้/ข้อเสนอเชิงนโยบาย ด้านเกษตรอินทรีย์ที่ได้รับการใช้ประโยชน์สู่สาธารณะ/ชุมชน 3.2 เครือข่ายเกษตรกร หรือผู้ประกอบการด้านเกษตรอินทรีย์ 4. ด้านภาพลักษณ์เกษตรอินทรีย์แม่โจ้และการบริหารจัดการ 4.1 การพัฒนาฐานข้อมูลเกษตรอินทรีย์ มหาวิทยาลัยแม่โจ้ 4.2 ความสำเร็จของ Maejo PGS 4.3 ความสำเร็จของกาด 2477 4.4 จำนวนพื้นที่อินทรีย์ภายในมหาวิทยาลัยที่ผ่านการรับรอง-
A14: 1.2.2 ความสำเร็จของการดำเนินงานด้านเกษตรอัจฉริยะ (Intelligent Agriculture) | B14: ร้อยละ | C14: 90 | D14: 75 | E14: =D14*100/C14 -> 83.333333 | F14: อ้างอิงข้อมูลจากส่วนกลาง | G14: พิจารณาจากผลการดำเนินงานกิจกรรมสำคัญที่จะขับเคลื่อนการดำเนินงานในปีงบประมาณ พ.ศ. 2569 ดังนี้ 1.ผลงานการเรียนการสอนด้านเกษตรอัจฉริยะ 1.1 หลักสูตรด้านเกษตรอัจฉริยะ (Degree/non-degree) ที่เปิดสอน (ในปีงบประมาณ 2569) 1.2 จำนวณบัณฑิต หรือ ผู้จบหลักสูตรด้านเกษตรอัจฉริยะ 2.ผลงานวิจัยด้านเกษตรอัจฉริยะ 2.1 จำนวนโครงการวิจัยด้านเกษตรอัจฉริยะ 3. ผลงานการบริการวิชาการด้านเกษตรอัจฉริยะ 3.1 จำนวนเทคโนโลยี นวัตกรรมและกระบวนการเกษตรสมัยใหม่และเกษตรอัจฉริยะที่ได้รับการพัฒนาต่อยอดกับชุมชน สังคม หรือพาณิชย์ 3.2 จำนวนเครือข่ายความร่วมมือและจำนวนเครือข่ายที่ได้รับการพัฒนาและขยายความร่วมมือกับกลุ่มผู้ใช้นวัตกรรมเกษตรสมัยใหม่และเกษตรอัจฉริยะ 4. ด้านภาพลักษณ์เกษตรอัจฉริยะแม่โจ้ 4.1 จำนวนพื้นที่/ศูนย์ถ่ายทอดนวัตกรรม/แหล่งเรียนรู้ และฟาร์มเกษตรสมัยใหม่และเกษตรอัจฉริยะภายในมหาวิทยาลัย
A15: 2.1.3 ความสำเร็จในการพัฒนานักศึกษาสู่การเป็นผู้มีสุขภาวะที่ดี | B15: ร้อยละ | C15: 90 | D15: 95 | E15: 100 | F15: รอข้อมูลจากส่วนกลาง | G15: พิจารณาจากความสำเร็จของการบรรลุเป้าหมายตามตัวชี้วัดและกิจกรรมโครงการที่กำหนดดังนี้ กิจกรรมที่จะดำเนินการ 1. กิจกรรมกวดขันวินัยและสร้างจิตสำนึกวินัยจราจร (ศึกษาวิจัย) (ZT) 2. การสำรวจสุขภาพจิต (แบบสำรวจสุขภาพจิต)นักศึกษาและบุคลากร (HP) 3. กิจกรรมส่งเสริมสุขภาพให้แก่นักศึกษาและบุคลากรในกลุ่มเสี่ยงจากข้อมูลการตรวจสุขภาพประจำปีบุคลกรและข้อมูลรายงานสุขภาพนักศึกษา(HP) 4. การดำเนินงานเพื่อพัฒนานักศึกษาสู่การเป็นผู้มีสุขภาวะที่ดีของแต่ละส่วนงาน
A16: ประเด็นยุทธศาสตร์ที่ 2. การขับเคลื่อนผลการดำเนินงานตามพันธกิจหลัก (Driving Mission - Driven Performance)
A17: เป้าประสงค์ที่ 2.1 ผลิตบัณฑิตและพัฒนานักศึกษาที่ก้าวทันต่อโลกสมัยใหม่และเป็นนักปฏิบัติที่เชี่ยวชาญ
A18: 2.1.1 จำนวนนักศึกษาใหม่ระดับปริญญาตรี | B18: คน | C18: 130 | D18: 133 | E18: 100 | F18: ข้อมูลนักศึกษาใหม่ระดับปริญญาตรี ปีการศึกษา 2569 | G18: พิจารณาจากการนับจำนวนนักศึกษารับเข้าระดับปริญญาตรี (ทั้งภาคปกติและสมทบ) ลงทะเบียนเข้าศึกษาชั้นปีที่1 ในหลักสูตรทุกประเภท ประจำปีการศึกษา 2569
A19: 2.1.2 ร้อยละของผู้สำเร็จการศึกษาภายในระยะเวลาของหลักสูตร | B19: ร้อยละ | C19: 80 | D19: 0 | E19: =IF((D19*100)/C19>=100,100,(D19*100)/C19) -> 0 | F19: ยังไม่มีผลการดำเนินงาน | G19: พิจารณาจากจำนวนนักศึกษาชั้นปีสุดท้ายระดับปริญญาตรี (ภาคปกติ) หลักสูตร 4 ปีและ 5 ปี สำเร็จการศึกษาในปีการศึกษา 2569 / จำนวนนักศึกษาหลักสูตร 4 ปีและ 5 ปี ชั้นปีสุดท้ายทั้งหมด) x 100
A20: 2.1.3 ร้อยละของบัณฑิตที่มีงานทำหรือประกอบอาชีพอิสระภายใน 1 ปี | B20: ร้อยละ | C20: 80 | D20: 74.29 | E20: =IF((D20*100)/C20>=100,100,(D20*100)/C20) -> 92.8625 | F20: มีบัณฑิตตอบแบบสอบถาม จำนวน 91 คน มีงานทำ จำนวน 76 คน | G20: พิจารณาจากจำนวนบัณฑิตระดับปริญญาตรีที่สำเร็จในปีการศึกษา 2567 ที่ได้งานทำหรือประกอบอาชีพอิสระภายใน 1 ปี / จำนวนบัณฑิตที่ตอบแบบสำรวจทั้งหมด) X 100
A21: 2.1.4 ความพึงพอใจผู้ใช้บัณฑิต | B21: ค่าเฉลี่ย | C21: 4.4 | D21: N/A | E21: N/A | F21: รอข้อมูลจากส่วนกลาง | G21: พิจารณาจากค่าเฉลี่ยผลการสำรวจความพึงพอใจของผู้ใช้บัณฑิต ประจำปีการศึกษา 2567 จากระบบความพึงพอใจของผู้ใช้บัณฑิต
A22: 2.1.5 รายได้เริ่มต้นเฉลี่ยต่อเดือนของบัณฑิตระดับปริญญาตรี | B22: บาท | C22: 15000 | D22: 15840 | E22: =IF((D22*100)/C22>=100,100,(D22*100)/C22) -> 100 | F22: อ้างอิงข้อมูลจากส่วนกลาง | G22: พิจารณาจากจำนวนรายได้เฉลี่ยต่อเดือนเริ่มต้นของบัณฑิตปริญญาตรีที่สำเร็จการศึกษา ในปีการศึกษา 2567
A23: 2.1.6ค่าฐานนิยม (Mode) ผลการประเมินระดับหลักสูตร | B23: ค่าเฉลี่ย | C23: 3 | D23: N/A | E23: N/A | F23: รอผลการประเมินของหลักสูตร | G23: พิจารณาจากค่าฐานนิยม (Mode) จากผลการประเมินคุณภาพการศึกษาระดับหลักสูตรตามเกณฑ์ AUN-QA ของทุกหลักสูตรในปีการศึกษา 2568 **ข้อมูลอ้างอิงจากระบบรายงานผลการประเมินคุณภาพการศึกษา (QA-Report)
A24: 2.1.7 จำนวนรายวิชาเรียนรู้ตลอดชีวิต | B24: รายวิชา | C24: 2 | D24: 2 | E24: =IF((D24*100)/C24>=100,100,(D24*100)/C24) -> 100 | F24: 1. นวัตกรรมปลาน้ำจืดสำหรับผู้ประกอบการ โดยรองศาสตราจารย์ ดร.เกรียงศักดิ์ เม่งอำพัน มีจำนวนผู้ลงทะเบียนเรียน 192 คน สำเร็จการศึกษา 44 คน 2. หลักสูตรนวัตกรรมการเพิ่มมูลค่าผลผลิตทางการเกษตรเพื่อ ขับเคลื่อนเศรษฐกิจ BCG (กลุ่มอุตสาหกรรมเกษตร สมัยใหม่และการแปรรูปอาหาร) (โครงการบัณฑิตพันธุ์ใหม่ฯ) | G24: พิจารณาจากการนับจำนวนรายวิชาเรียนรู้ตลอดชีวิตที่คณะกรรมการวิชาการรับทราบ และมีการเปิดรับนักศึกษาในปีงบประมาณ พ.ศ. 2569
A25: 2.1.8 จำนวนรางวัลที่นักศึกษา บุคลากร ศิษย์เก่าหรือส่วนงาน ได้รับในระดับชาติ หรือนานาชาติ | B25: รางวัล | C25: 5 | D25: 19 | E25: =IF((D25*100)/C25>=100,100,(D25*100)/C25) -> 100 | F25: คณะมีจำนวนรางวัลที่นักศึกษา บุคลากร ศิษย์เก่า หรือส่วนงาน ได้รับในระดับชาติ หรือนานาชาติ จำนวน 12 รางวัล ได้แก่ 1. รางวัล Best Poster Presentation Award จากผลงาน เรื่อง Preliminary Study on Semantic Segmentation of Head, Tail, Fins, and Body of Nile Tilapia Using Deep Convolutional Neural Networks with Transfer Learning ของ รศ.ดร.นิสรา กิจเจริญ 2. รางวัลการนำเสนอผลงานภาคบรรยายระดับดีมาก เรื่อง การเปรียบเทียบสูตรอาหารที่เหมาะสมในการเพาะเลี้ยงคลอเรลล่าของ นายคณัสนันท์ จันต๊ะมงคล 3. รางวัลการนำเสนอผลงานภาคบรรยายระดับดีมาก เรื่อง แนวทางการเสริมสร้างศักยภาพธุรกิจปลาดุกในห่วงโซ่การผลิตพื้นที่อำเภอสันทราย จังหวัดเชียงใหม่ ของ นายชิณเสฏฐ์ เอี่ยมเมือง 4. รางวัลการนำเสนอผลงานภาคบรรยายระดับดี เรื่อง การพัฒนาสูตรอาหารปลานิลอินทรีย์จากวัตถุดินอินทรีย์เสริมชีวมวลไบโอฟลอค : การประเมินประสิทธิภาพการเจริญเติบโตและต้นทุนการผลิต ของ น.ส.พิชญาภา พิทักษ์วัชรีกุล 5. รางวัลการนำเสนอผลงานภาคบรรยายระดับดีมาก เรื่อง ประสิทธิภาพการเจริญเติบโตของปลานิลที่เลี้ยงด้วยอาหารผสมกากมะพร้าวหมักที่ระดับแตกต่างกัน ของ น.ส.พุทธิดา สมบูรณ์ชัย 6. รางวัลการนำเสนอผลงานภาคโปสเตอร์ระดับดีมาก เรื่อง ผลของชนิดพริก วิธีการทำแห้ง ชนิดของบรรจุภัณฑ์ และวิธีการฆ่าเชื้อที่มีต่อคุณลักษณะของน้ำพริกน้ำปู ของ น.ส.เพ็ญนภา ชูเยาว์ 7. รางวัลการนำเสนอผลงานภาคบรรยายระดับดีเยี่ยม เรื่อง การศึกษาทางอนุกรมวิธาน และการค้นพบปลาค้อชนิดใหม่จากลำน้ำเข็ก อำเภอเขาค้อ จังหวัดเพชรบูรณ์ ของ นายภัคพล ชุมศิลป์ 8. รางวัลการนำเสนอผลงานภาคโปสเตอร์ระดับดีเยี่ยม เรื่อง การพัฒนาผลิตภัณฑ์ปลาบึกทอดกรอบจากวัตถุดิบที่ผ่านการบ่มแบบเปียกโดยการคัดกรองปัจจัยด้วยการออกแบบการทดลองแบบ Plackett-Burman ของ อ.ดร.นงพงา แสงเจริญ 9. รางวัลระดับชาติเชิดชูเกียรติ "คนดีศรีเกษตร" งานกีฬาประเพณี 4 จอบ แห่งชาติ ครั้งที่ 40 10. รางวัลระดับชาติเหรียญทอง "ทักษะการบรรจุพันธุ์ลูกปลา" งานกีฬาประเพณี 4 จอบ แห่งชาติ ครั้งที่ 40 11. รางวัลระดับชาติเหรียญทอง "การประกวดโมเดลธุรกิจนวัตกรรมการเกษตร" งานกีฬาประเพณี 4 จอบ แห่งชาติ ครั้งที่ 40 12. รางวัลระดับชาติเหรียญทอง "ทักษะการทอดแห" งานกีฬาประเพณี 4 จอบ แห่งชาติ ครั้งที่ 40 13. รางวัลนำเสนอผลงานระดับนานาชาติ BEST ORAL PRESENTATION AWARD เรื่อง “Performance of Selected Heterotrophic Bacteria in Different Formulations for Biofloc System Development in Nile Tilapia” | G25: พิจารณาจากการนับจำนวนรางวัลจำนวนรางวัลที่นักศึกษา บุคลากร ศิษย์เก่า หรือส่วนงาน/หน่วยงานได้รับในระดับชาติ/นานาชาติ ในปีงบประมาณ พ.ศ. 2569
F26: 14. รางวัลประกวดผลงานนวัตกรรมระดับนานาชาติ SPECIAL AWARD เรื่อง From Manual to AI: Real-Time Fish Fry Counting System 15. รางวัลประกวดผลงานนวัตกรรมระดับนานาชาติ SILVER เรื่อง River Digital Twin with LSTM-Based Water Quality Forecasting for Cage Aquaculture Early Warning System along the Ping River, Thailand 16. รางวัลประกวดผลงานนวัตกรรมระดับนานาชาติ SPECIAL AWARD เรื่อง From Waste to Protein: Microbial Innovation for Zero Water-Exchange Aquaculture 17. รางวัลเหรียญทองแดง ฟรีสไตล์ 50 เมตร จากการแข่งขันกีฬาบุคลากรมหาวิทยาลัยแห่งประเทศไทย ครั้งที่ 42 “มศว เกมส์” 18. รางวัลเหรียญเงิน ผลัดฟรีสไตล์ 4x50 เมตร จากการแข่งขันกีฬาบุคลากรมหาวิทยาลัยแห่งประเทศไทย ครั้งที่ 42 “มศว เกมส์” 19. รางวัลเหรียญเงิน ผลัดผสม 4x50 เมตร จากการแข่งขันกีฬาบุคลากรมหาวิทยาลัยแห่งประเทศไทย ครั้งที่ 42 “มศว เกมส์”
A27: 2.1.9 ร้อยละของนักศึกษาชั้นปีสุดท้ายที่ผ่านกระบวนการ พัฒนาพัฒนาให้เป็นพลเมืองโลก ด้วยกระบวนการทักษะในศตวรรษที่ 21 | B27: ร้อยละ | C27: 90 | D27: 100 | E27: =IF((D27*100)/C27>=100,100,(D27*100)/C27) -> 100 | F27: ร้อยละของนักศึกษาชั้นปีสุดท้ายที่ผ่านกระบวนการ พัฒนาพัฒนาให้เป็นพลเมืองโลก ด้วยกระบวนการทักษะในศตวรรษที่ 21 ร้อยละ 100 | G27: พิจารณาจากจำนวนนักศึกษาชั้นปีสุดท้ายที่ได้รับการพัฒนาตามกระบวนการพัฒนาทักษะการเรียนรู้ในศตวรรษที่ 21 / จำนวนนักศึกษาชั้นปีสุดท้ายทั้งหมด) x 100
A28: เป้าประสงค์ที่ 2.2 สร้างผลงานวิจัย เทคโนโลยีและนวัตกรรม ที่มีการบูรณาการศาสตร์ โดยใช้เกษตรเป็นรากฐาน และได้รับการยอมรับในระดับชาติและนานาชาติ
A29: 2.2.1 จำนวนเงินวิจัยด้านวิทยาศาสตร์และเทคโนโลยี | B29: บาท | C29: 5167959 | D29: 9088219 | E29: =IF((D29*100)/C29>=100,100,(D29*100)/C29) -> 100 | F29: ในปีงบประมาณ 2569 คณะฯ มีเงินสนับสนุนงานวิจัย จำนวน 9,088,219 บาท โดยแบ่งออกเป็นแหล่งทุนงานวิจัยภายใน จำนวน 2,034,440 บาท และเป็นทุนงานวิจัยจากภายนอก จำนวน 7,053,779 บาท ต่ออาจารย์ประจำที่ปฏิบัติงานจริง จำนวน 15 คน ดังนั้น จึงคิดเป็นจำนวน 605,881.27 บาท ต่อคน | G29: พิจารณาจากจำนวนเงินสนับสนุนโครงการวิจัยจากทุกแหล่งงบประมาณ (งบประมาณแผ่นดินและงบประมาณจากแหล่งอื่น) ที่อาจารย์/นักวิจัยประจำได้รับ ที่ได้ขึ้นทะเบียนงานวิจัยที่สำนักวิจัยฯ และบันทึกเข้าสู่ฐานข้อมูลงานวิจัยในระบบ ERP
A30: 2.2.2 ร้อยละของอาจารย์และนักวิจัยประจำที่มีผลงานวิจัย | B30: ร้อยละ | C30: 70 | D30: 60 | E30: =IF((D30*100)/C30>=100,100,(D30*100)/C30) -> 85.714286 | F30: อาจารย์ประจำที่มีงานวิจัย จำนวน 9 คน ต่อจำนวนอาจารย์ประจำที่ปฏิบัติงานจริง 15 คน คิดเป็นร้อยละ 60 โดยมีรายชื่ออาจารย์ที่ได้รับทุน ดังนี้ 1. ผศ.ดร.สุดาพร ตงศิริ 2. รศ.ดร.ชนกันต์ จิตมนัส 3. อ.ดร.โดม อดุลย์สุข 4. อ.ดร.วาธิณี อินทรพงษ์นุวัฒน์ 5. รศ.ดร.จงกล พรมยะ 6. อ.ดร.ขจรเกียรติ์ ศรีนวลสม 7. อ.ดร.นงพงา แสงเจริญ 8. รศ.ดร.ดวงพร อมรเลิศพิศาล 9. ผศ.ดร.ดารชาต์ เทียมเมือง | G30: พิจารณาจากจำนวนอาจารย์และนักวิจัยประจำที่มีผลงานวิจัยนับเฉพาะที่เป็นหัวหน้าโครงการหรือมีความรับผิดชอบในโครงการวิจัยนั้นๆ ในปีงบประมาณ พ.ศ. 2569
A31: 2.2.3 จำนวนครั้งในการผลงานวิจัยหรืองานสร้างสรรค์ที่นำไปใช้ประโยชน์ | B31: ครั้ง | C31: 3 | D31: 8 | E31: =IF((D31*100)/C31>=100,100,(D31*100)/C31) -> 100 | F31: คณะฯ มีการนำผลงานวิจัยหรืองานสร้างสรรค์ไปใช้ประโยชน์ จำนวน 8 ครั้ง ได้แก่ 1. นำงานวิจัย เรื่อง ศึกษาประสิทธิภาพระบบเลี้ยงปลาดุกและปลูกผักในบ้านอัจฉริยะ ไปใช้ประโยชน์แก่ภาควิชาสัตวศาสตร์และสัตว์น้ำ คณะเกษตรศาสตร์ มหาวิทยาลัย เชียงใหม่ 2. นำงานวิจัย เรื่อง ศึกษาประสิทธิภาพระบบเลี้ยงปลาดุกและปลูกผักในบ้านอัจฉริยะ ไปใช้ประโยชน์แก่คณะเทคโนโลยีการเกษตร มหาวิทยาลัยราชภัฏเชียงใหม่ 3. นำงานวิจัย เรื่อง โครงการการพัฒนาผลิตภัณฑ์ซินไบโอติกส์ร่วมกับวัสดุเหลือทิ้งทางการเกษตร เพื่อลดการใช้ยาปฏิชีวนะในสัตว์น้ำ ไปใช้ประโยชน์แก่บริษัท อุตสาหกรรม เทคโนโลยี ชีวภาพ (ประเทศไทย) จำกัด 4. นำงานวิจัย เรื่อง ประสิทธิภาพของชีวภัณฑ์ shrimp premix และ MEX1 ต่อสุขภาพและผลผลิตของกุ้งเศรษฐกิจ ไปใช้ประโยชน์แก่บริษัท อุตสาหกรรม เทคโนโลยี ชีวภาพ (ประเทศไทย) จำกัด 5. นำงานวิจัย เรื่อง ประสิทธิภาพของชีวภัณฑ์ fish premix และ THEPTM1 ต่อการเจริญเติบโตและคุณภาพของปลานิล ไปใช้ประโยชน์แก่บริษัท อุตสาหกรรม เทคโนโลยี ชีวภาพ (ประเทศไทย) จำกัด 6. นำงานวิจัย เรื่อง การผลิตสารสกัดจากส่วนดอกและใบดาหลา 2 ชนิด ไปใช้ประโยชน์แก่วิสาหกิจชุมชนมั่นคง มั่งคั่ง ยั่งยืน 7. นำงานวิจัย เรื่อง การขยายสเกลการผลิตสารเสริมโปรตีนปลาไฮโดรไลเสตสำหรับเป็นสารเสริมกระตุ้นการกินในสัตว์เลี้ยง ระดับกึ่งอุตสาหกรรม ไปใช้ประโยชน์แก่บริษัท นิวทรีชั่น เอสซี จำกัด (มหาชน) 8. นำงานวิจัย เรื่อง การขยายสเกลการผลิตและทดสอบทางคลินิกของผลิตภัณฑ์มูลค่าเพิ่มจากส่วนเหลือใช้การแปรรูปปลาลูกผสมบึกสยามแม่โจ้ ไปใช้ประโยชน์แก่บริษัท เซนทอล จำกัด | G31: พิจารณาจากจำนวนครั้งในการนำผลงานวิจัยหรืองานสร้างสรรค์ของอาจารย์/นักวิจัยประจำที่มีการนำมาใช้ประโยชน์ในปีงบประมาณ พ.ศ. 2569
A32: 2.2.4 ร้อยละของผลงานวิจัยที่ได้รับการตีพิมพ์เผยแพร่ตามเกณฑ์การเผยแพร่ผลงานวิชาการของ กพอ. | B32: ร้อยละ | C32: 50 | D32: 106.25 | E32: =IF((D32*100)/C32>=100,100,(D32*100)/C32) -> 100 | F32: งานวิจัยหรืองานสร้างสรรค์ที่ได้รับการตีพิมพ์หรือเผยแพร่ จำนวน 17 เรื่อง คิดคะแนนถ่วงน้ำหนัก เท่ากับ 16.00 ต่อจำนวนอาจารย์ประจำและลาศึกษาต่อ จำนวน 16 คน คิดเป็นร้อยละ 106.25 - ฐานข้อมูล TCI กลุ่ม 2 จำนวน 1 เรื่อง - ฐานข้อมูล TCI กลุ่ม 1 จำนวน 3 เรื่อง - ฐานข้อมูลระดับนานาชาติ 13 เรื่อง | G32: พิจารณาจากจำนวนผลงานวิจัยหรืองานสร้างสรรค์ที่ได้รับการตีพิมพ์ระดับชาติหรือนานาชาติ / จำนวนอาจารย์และนักวิจัยประจำทั้งหมด) x 100
A33: 2.2.5 ร้อยละของบทความวิจัยที่ได้รับการอ้างอิง (Citation) ต่อจำนวนอาจารย์ประจำทั้งหมด | B33: ร้อยละ | C33: 110 | D33: 1112.5 | E33: =IF((D33*100)/C33>=100,100,(D33*100)/C33) -> 100 | F33: ในปีงบประมาณ 2569 คณะฯ มีผลการดำเนินงานด้านบทความวิจัยที่ได้รับการอ้างอิง (Citation) ใน Refereed journal หรือในฐานข้อมูลระดับนานาชาติ จำนวน 178 เรื่อง (ข้อมูลวันที่ 27 มีนาคม 2569) ต่ออาจารย์ประจำที่ปฏิบัติงานจริงและลาศึกษาต่อ จำนวน 16 คน คิดเป็นร้อยละ 1,112.50 | G33: พิจารณาจากบทความวิจัยหรืองานสร้างสรรค์ที่ได้รับการอ้างอิง (Citation) ใน (Refereed journal หรือในฐานข้อมูลระดับนานาชาติ / จำนวนอาจารย์และนักวิจัยประจำทั้งหมด) x 100* นับอาจารย์ลาศึกษาต่อ
A34: 2.2.6 จำนวนผลงานวิจัยที่ยื่นขอจดสิทธิบัตร/อนุสิทธิบัตร/บัญชีนวัตกรรม/นวัตกรรมต้นแบบ | B34: ผลงาน | C34: 2 | D34: 1 | E34: =IF((D34*100)/C34>=100,100,(D34*100)/C34) -> 50 | F34: ผลงานวิจัยหรืองานสร้างสรรค์ของอาจารย์ประจำที่เสนอขอรับการจดทะเบียนสิทธิบัตร/อนุสิทธิบัตร จำนวน 6 ผลงาน ได้แก่ 1. ยื่นขอการจดทะเบียนอนุสิทธิบัตร สูตรขนมเลียผสมซินไบโอติกสำหรับแมว โดย รศ.ดร.ดวงพร อมรเลิศพิศาล | G34: พิจารณาจากการนับจำนวนผลงานวิจัยที่ได้ยื่นขอจดสิทธิบัตร/อนุสิทธิบัตร/บัญชีนวัตกรรม/นวัตกรรมต้นแบบ
A35: 2.2.7 ร้อยละของผลงานวิชาการที่เสนอขอรับการจดลิขสิทธิ์ต่ออาจารย์ประจำ | B35: ร้อยละ | C35: 60 | D35: 18.75 | E35: =IF((D35*100)/C35>=100,100,(D35*100)/C35) -> 31.25 | F35: ในปีงบประมาณ 2569 คณะฯ มีผลงานวิชาการที่เสนอขอรับการจดลิขสิทธิ์ จำนวน 3 เรื่อง ต่อจำนวนอาจารย์ประจำทั้งหมด 16 คน คิดเป็นร้อยละ 18.75 | G35: พิจารณาจากจำนวนผลงานวิชาการที่เสนอขอรับการจดลิขสิทธิ์และ/หรือได้รับรองคุณภาพจากหน่วยงานที่เชื่อถือได้ ภายในปีงบประมาณ พ.ศ. 2569 ต่อจำนวนอาจารย์ประจำทั้งหมด
A36: 2.2.8 จำนวนองค์ความรู้งานวิจัยเพื่อพัฒนาผู้เรียน | B36: เรื่อง | C36: 10 | D36: 15 | E36: =IF((D36*100)/C36>=100,100,(D36*100)/C36) -> 100 | F36: มีการนำองค์ความรู้งานวิจัยมาประยุกต์ใช้ในการเรียนการสอน เพื่อพัฒนาผู้เรียน จำนวน 15 เรื่อง | G36: พิจารณาจากจำนวนองค์ความรู้งานวิจัยที่นำมาสู่การพัฒนาผู้เรียน ในปีงบประมาณ พ.ศ. 2569
A37: เป้าประสงค์ที่ 2.3 ให้บริการวิชาการเพื่อเป็นที่ยอมรับจากสังคม ชุมชน และประเทศ ด้วยศาสตร์ทางด้านการเกษตร
A38: 2.3.1 จำนวนงบประมาณบริการวิชาการ | B38: บาท | C38: 745000 | D38: 745000 | E38: =IF((D38*100)/C38>=100,100,(D38*100)/C38) -> 100 | F38: มีจำนวน 10 โครงการ | G38: พิจารณาจากการนับจำนวนงบประมาณบริการวิชาการจากทุกแหล่งทุน ในปีงบประมาณ พ.ศ. 2569
A39: 2.3.2 ผลกระทบด้านเศรษฐกิจ สังคม และคุณภาพชีวิตของชุมชนจากการบริการวิชาการ | B39: ค่าเฉลี่ย | C39: 4 | D39: N/A | E39: N/A | F39: รอผลประเมินเมื่อสิ้นสุดการจัดทำโครงการ | G39: พิจารณาจากค่าเฉลี่ยผลการสำรวจผลกระทบด้านเศรษฐกิจ สังคม และคุณภาพชีวิตของชุมชนเป้าหมาย ที่เกิดจากโครงการบริการวิชาการของมหาวิทยาลัยและส่วนงาน
A40: 2.3.3 ระดับความสำเร็จของการบูรณาการผลงานบริการวิชาการสู่พันธกิจอื่น | B40: ระดับ | C40: 5 | D40: 1.67 | E40: =D40*100/C40 -> 33.4 | F40: ปีงบประมาณ 2569 คณะฯ มีโครงการบริการวิชาการแก่สังคมตามแผนปฏิบัติการฯ จำนวน 10 โครงการ โดยมีโครงการบริการวิชาการ จำนวน 1 โครงการ ที่ได้นำองค์ความรู้ด้านบริการวิชาการไปบูรณาการเข้ากับพันธกิจอื่น ๆ ดังนั้น ผลการดำเนินงานจึงคิดเป็นร้อยละ 10 เมื่อนำมาเทียบบัญญัติไตรยางศ์ โดยกำหนดร้อยละ 30 เท่ากับ 5 คะแนน ผลการดำเนินงานเท่ากับ 1.67 (ส่วนโครงการที่เหลืออยู่ระหว่างดำเนินการ) | G40: พิจารณาจากจำนวนผลการนำความรู้และประสบการณ์จากการให้บริการวิชาการมาใช้ในการพัฒนาการเรียนการสอนและ/หรือการวิจัยต่อจำนวนโครงการบริการวิชาในแผนปฏิบัติการประจำปีงบประมาณ พ.ศ. 2569 โดยเทียบบัญญัติไตรยางศ์กำหนดร้อยละ 30 เท่ากับ 5 คะแนน
A41: เป้าประสงค์ที่ 2.4 เป็นแหล่งเรียนรู้ด้านศิลปวัฒนธรรมเกษตรและสิ่งแวดล้อม และสร้างสรรค์นวัตกรรมด้านทุนทางวัฒนธรรม
...

Sheet สรุป 9 เดือน 69
A1: สรุปร้อยละความสำเร็จตัวชี้วัดตามตัวชี้วัดตามแผนพัฒนาการศึกษา ระยะที่ 13 (พ.ศ.2565 - 2569) และแผนปฏิบัติการ ประจำปีงบประมาณ พ.ศ. 2569
A2: คณะเทคโนโลยีการประมงและทรัพยากรทางน้ำ รอบ 9 เดือน (1 ตุลาคม 2568 - 30 มิถุนายน 2569)
A3: ประเด็นยุทธศาสตร์ | B3: จำนวนตัวชี้วัด | F3: ร้อยละความสำเร็จ ตามเป้าหมายเฉลี่ย | H3: ปัญหา/อุปสรรค และแนวทางปรับปรุง ผลการดำเนินในแต่ละประเด็นยุทธศาสตร์
B4: ผลการดำเนินงาน รอบ 6 เดือน
B5: รวม | C5: บรรลุเป้าหมาย | D5: ไม่บรรลุเป้าหมาย | E5: N/A | F5: รอบ 6 เดือน | G5: รอบ 9 เดือน
A6: ประเด็นยุทธศาสตร์ที่ 1 (Proactive Strategy toward Inter IWA) | B6: =SUM(C6:E6) -> 8 | C6: 2 | D6: 6 | E6: 0 | F6: =AVERAGE('ตัวชี้วัด 69 (6 เดือน)'!E7:E11,'ตัวชี้วัด 69 (6 เดือน)'!E13:E15) -> 46.762607
A7: ประเด็นยุทธศาสตร์ที่ 2 การขับเคลื่อนผลการดำเนินงานตามพันธกิจหลัก | B7: =SUM(C7:E7) -> 16 | C7: =SUM(C8:C11) -> 10 | D7: 0 | E7: =SUM(E8:E11) -> 6 | F7: =AVERAGE('ตัวชี้วัด 69 (6 เดือน)'!E19,'ตัวชี้วัด 69 (6 เดือน)'!E20,'ตัวชี้วัด 69 (6 เดือน)'!E22,'ตัวชี้วัด 69 (6 เดือน)'!E24,'ตัวชี้วัด 69 (6 เดือน)'!E25,'ตัวชี้วัด 69 (6 เดือน)'!E26,'ตัวชี้วัด 69 (6 เดือน)'!E28,'ตัวชี้วัด 69 (6 เดือน)'!E29,'ตัวชี้วัด 69 (6 เดือน)'!E30,'ตัวชี้วัด 69 (6 เดือน)'!E31,'ตัวชี้วัด 69 (6 เดือน)'!E32,'ตัวชี้วัด 69 (6 เดือน)'!E33,'ตัวชี้วัด 69 (6 เดือน)'!E34,'ตัวชี้วัด 69 (6 เดือน)'!E35,'ตัวชี้วัด 69 (6 เดือน)'!E37,'ตัวชี้วัด 69 (6 เดือน)'!E42) -> 78.739174
A8: - ด้านผลิตบัณฑิต | B8: =SUM(C8:E8) -> 9 | C8: 4 | D8: 2 | E8: 3 | F8: =AVERAGE('ตัวชี้วัด 69 (6 เดือน)'!E19,'ตัวชี้วัด 69 (6 เดือน)'!E20,'ตัวชี้วัด 69 (6 เดือน)'!E22,'ตัวชี้วัด 69 (6 เดือน)'!E24,'ตัวชี้วัด 69 (6 เดือน)'!E25,'ตัวชี้วัด 69 (6 เดือน)'!E26) -> 82.14375
A9: - ด้านวิจัยและนวัตกรรม | B9: =SUM(C9:E9) -> 8 | C9: 5 | D9: 3 | E9: 0 | F9: =AVERAGE('ตัวชี้วัด 69 (6 เดือน)'!E28,'ตัวชี้วัด 69 (6 เดือน)'!E29,'ตัวชี้วัด 69 (6 เดือน)'!E30,'ตัวชี้วัด 69 (6 เดือน)'!E31,'ตัวชี้วัด 69 (6 เดือน)'!E32,'ตัวชี้วัด 69 (6 เดือน)'!E33,'ตัวชี้วัด 69 (6 เดือน)'!E34,'ตัวชี้วัด 69 (6 เดือน)'!E35) -> 83.370536
A10: - ด้านบริการวิชาการแก่สังคม | B10: =SUM(C10:E10) -> 3 | C10: 1 | D10: 0 | E10: 2 | F10: =AVERAGE('ตัวชี้วัด 69 (6 เดือน)'!E37) -> 100
A11: - ด้านทำนุบำรุงศิลปวัฒนธรรม | B11: =SUM(C11:E11) -> 2 | C11: 0 | D11: 1 | E11: 1 | F11: =AVERAGE('ตัวชี้วัด 69 (6 เดือน)'!E42) -> 0
A12: ประเด็นยุทธศาสตร์ที่ 3 การขับเคลื่อนความเป็นนานาชาติ | B12: =SUM(C12:E12) -> 5 | C12: 0 | D12: 4 | E12: 1 | F12: =AVERAGE('ตัวชี้วัด 69 (6 เดือน)'!E45,'ตัวชี้วัด 69 (6 เดือน)'!E46,'ตัวชี้วัด 69 (6 เดือน)'!E48,'ตัวชี้วัด 69 (6 เดือน)'!E51) -> 52.5
A13: ประเด็นยุทธศาสตร์ที่ 4 การขับเคลื่อนสู่การเป็นมหาวิทยาลัยด้านการพัฒนาเทคโนโลยีและส่งเสริมการสร้างนวัตกรรม | B13: =SUM(C13:E13) -> 3 | C13: 1 | D13: 2 | E13: 0 | F13: =AVERAGE('ตัวชี้วัด 69 (6 เดือน)'!E56:E59) -> 60
A14: ประเด็นยุทธศาสตร์ที่ 5 การบริหารจัดการและการเสริมสร้างความมั่นคงทางการเงินอย่างยั่งยืน | B14: =SUM(C14:E14) -> 8 | C14: 3 | D14: 2 | E14: 3 | F14: =AVERAGE('ตัวชี้วัด 69 (6 เดือน)'!E66,'ตัวชี้วัด 69 (6 เดือน)'!E69,'ตัวชี้วัด 69 (6 เดือน)'!E70,'ตัวชี้วัด 69 (6 เดือน)'!E71,'ตัวชี้วัด 69 (6 เดือน)'!E73) -> 69.488286
A15: เฉลี่ยประเด็น 1-5 | B15: =B6+B7+B12+B13+B14 -> 40 | C15: =C6+C7+C12+C13+C14 -> 16 | D15: =D6+D7+D12+D13+D14 -> 14 | E15: =E6+E7+E12+E13+E14 -> 10 | F15: =AVERAGE('ตัวชี้วัด 69 (6 เดือน)'!E7,'ตัวชี้วัด 69 (6 เดือน)'!E8,'ตัวชี้วัด 69 (6 เดือน)'!E9,'ตัวชี้วัด 69 (6 เดือน)'!E10,'ตัวชี้วัด 69 (6 เดือน)'!E11,'ตัวชี้วัด 69 (6 เดือน)'!E13,'ตัวชี้วัด 69 (6 เดือน)'!E14,'ตัวชี้วัด 69 (6 เดือน)'!E15,'ตัวชี้วัด 69 (6 เดือน)'!E19,'ตัวชี้วัด 69 (6 เดือน)'!E20,'ตัวชี้วัด 69 (6 เดือน)'!E22,'ตัวชี้วัด 69 (6 เดือน)'!E24,'ตัวชี้วัด 69 (6 เดือน)'!E25,'ตัวชี้วัด 69 (6 เดือน)'!E26,'ตัวชี้วัด 69 (6 เดือน)'!E28,'ตัวชี้วัด 69 (6 เดือน)'!E29,'ตัวชี้วัด 69 (6 เดือน)'!E30,'ตัวชี้วัด 69 (6 เดือน)'!E31,'ตัวชี้วัด 69 (6 เดือน)'!E32,'ตัวชี้วัด 69 (6 เดือน)'!E33,'ตัวชี้วัด 69 (6 เดือน)'!E34,'ตัวชี้วัด 69 (6 เดือน)'!E35,'ตัวชี้วัด 69 (6 เดือน)'!E37,'ตัวชี้วัด 69 (6 เดือน)'!E42,'ตัวชี้วัด 69 (6 เดือน)'!E45,'ตัวชี้วัด 69 (6 เดือน)'!E46,'ตัวชี้วัด 69 (6 เดือน)'!E48,'ตัวชี้วัด 69 (6 เดือน)'!E51,'ตัวชี้วัด 69 (6 เดือน)'!E56,'ตัวชี้วัด 69 (6 เดือน)'!E57,'ตัวชี้วัด 69 (6 เดือน)'!E59,'ตัวชี้วัด 69 (6 เดือน)'!E66,'ตัวชี้วัด 69 (6 เดือน)'!E69,'ตัวชี้วัด 69 (6 เดือน)'!E70,'ตัวชี้วัด 69 (6 เดือน)'!E71,'ตัวชี้วัด 69 (6 เดือน)'!E73) -> 65.871363
A16: ระดับความสำเร็จ (คะแนนเต็ม 5) | F16: =F15*5/100 -> 3.2935682
C63: 5 | D63: 3
